Workbook

Sheet Model Health
A1: RealGold Financial Model - Corrected
A3: Version | B3: V2.4 - LibreOffice/Sheets Compatible
A4: Updated | B4: 2025-11-25 15:32
A6: Corrections
A7: Unitization Fee: 0.5% → 0.01%
A8: Courbet: Sep → Dec '25
A9: Mine 2: Nov '25 → Jan '26

Sheet Overview
A1: RealGold Financial Model Workbook
A2: Welcome to the Financial Model Workbook for RealGold. This model is designed to provide a transparent, dynamic, and scenario-driven view of our economic design.
A3: It outlines the key assumptions, inputs, mechanisms, and projected outcomes that support the viability, sustainability, and scalability of RealGold.
A4: The model is modular and interactive — feel free to explore each section to understand how various parameters shape the financial architecture.
A6: Sheets
A7: Summaries | B7: Charts representing top level summaries including Resources under Management, Cash Position, Cashflows, Revenue, and Token Supply/Demand.
A8: Inputs | B8: Primary assumptions live here. This includes gold spot price, collateralization ratios, unlock schedules, fee percentages, and other model-wide variables. This sheet powers dynamic calculations across the workbook.
A9: Mine Inventory | B9: Holds our working list of registered mines (currently dummy data for testing). Each mine’s resource classification (Measured, Indicated, Inferred), Tripartite committment, and unlock rates are here.
A10: Resource Supply (5yr) | B10: Calculates the yearly market availability of RealGold units based on the Mine Inventory and Trust commitments. This is where unitizable resources become released to market over a 20–40 year time horizon.
A11: Token Supply (5yr) | B11: Projects the circulating and total RealGold token counts over five years, incorporating unlock schedules and treasury allocations to forecast market‑cap and liquidity trajectories.
A12: Token Demand (5yr) | B12: Models how RealGold units trade once released to the market. Includes transfer volume assumptions and projected on-chain activity, which feed into token economics and fee revenue projections.
A13: Cashflow (RA LLC) | B13: A traditional cash flow statement for the Regenerative Assets LLC, tracking income, expenditures, and net position over time.
A14: Cashflow (RAF) (5yr) | B14: A traditional cash flow statement for the Real Assets Foundation, tracking income, expenditures, and net position over time.
A15: Cashflow (RGT) | B15: A traditional cash flow statement for the Real Gold Treasury, tracking income, expenditures, and net position over time.
A16: Personnel | B16: Outlines all team roles, titles, stipends, and salaries. Used to forecast payroll and model team growth over time.
A17: Deferred Comp | B17: Tracks the team deferred compensation issuances, redemptions, and remaining balances, linking operational spending and capital raises to outstanding Keepon obligations for accurate liability accounting.
A18: Capital | B18: Defines the capital strategy. Models tranches of funding, investor return mechanics (e.g., “keepons”), and capital return timing.
... A21: Expenditures | B21: Captures actual costs to date, including operations, legal, tech development, and compliance. Informs Keepon accumulation for project expenses to date.
A27: Assumptions
B28: Gold price of $2707 as of December 31st, 2024 with a CAGR of 7.8%
B29: Paying back our capital raised within 4 years
B30: ~8 million assayed ounces of gold-in-ground registered over 4 years from 12 mines
B31: No new inventory after 4 years in order to gauge annual recurring revenue
B32: Sensitivity analysis uses gold price of of 12/31/2024 + CAGR and assumes consistent 15% underperformance.

Sheet Summaries
A1: Summaries | J1: e

Sheet Inputs
A1: Realgold Financial Model Inputs
A3: Project Qualification Level | B3: Resource Unlock % | C3: Resource Holdback % | D3: Max Initial Release | E3: Release Years | F3: Review Cycle | G3: Qualifications under review for ongoing time-released funds
A4: Mineral Estate Trust | B4: =1-C4 | C4: 0.8 | D4: 0.2 | E4: 40 | F4: 5 years | G4: Gold is protected. No active mining. Enviornmental remediation plan being fulfilled. Remediation metrics met (80%+)
A5: Mineral + Bio Estate Trusts | B5: =1-C5 | C5: 0.65 | D5: 0.2 | E5: 30 | F5: 5 years | G5: Regen land management plan being fulfilled. Targets met (80%+) (+mining reqs)
A6: Mineral + Bio + Social Estate Trusts | B6: =1-C6 | C6: 0.5 | D6: 0.2 | E6: 20 | F6: 3 years | G6: All three trusts operational with their regen plans being fulfilled.
A8: Mineral Prices & Units
A9: Price of Gold (oz) (as of Dec. 31, 2024) | B9: 2711.6
A10: Gold Spot Price (as of Aug. 9, 2025) | B10: 3779
A11: Silver Spot Price | B11: 38.16
A12: Silver/Gold Ratio | B12: =B10/B11
A13: Silver/Gold Conversion Ratio | B13: 120
A14: Gold CAGR (historical over 25 yrs) | B14: 0.078
A15: AISC (NatGold Index) | B15: 1481.32
A16: Intrinsic Value (price of gold - AISC) | B16: =B10-B15
A17: Intrinsic Value (%) | B17: =B16/B9
A19: Valuation of Types of Mineral Resources
A20: Measured | B20: 1
A21: Indicated | B21: 0.75
A22: Inferred | B22: 0.5
A24: RealGold Fee Structure
A25: Yearly Admin Fee (on authorized assets) | B25: 0.0001
A26: Unitization Fee (linked to unlocks) | B26: 0.0001
A27: Liquidity Reserve Fee | B27: 0.01
A28: RealGold Token Minting Fee | B28: 0.005
A29: RealGold Token Transfer Tax | B29: 0.003
A31: Token Supply Scenarios (Sale of RG by Trusts)
A32: Conservative sales | B32: 0.25
A33: Moderate sales | B33: 0.5
A34: Aggressive sales | B34: 1
A36: Liquidity Variables
A37: Impermanent Loss (average) | B37: 0.01
A38: DEX Swap Fees | B38: 0.003
A40: Market-Making Variables
A41: Buy Price | B41: 0.99
A42: Sell Price | B42: 1.02
A43: Spread per oz (minus transfer & swap fees) | B43: =1+(1*Inputs!B42)-(1*Inputs!B41)-(1*Inputs!B29)-(1*Inputs!B38)
A44: Volatility
A46: Compensation Multipliers
A47: Target 1 | B47: 1.5
A48: Target 2 | B48: 2
...

Sheet Mine Inventory
A1: Mine Inventory | C1: Mea. Au (oz) | D1: Ind. Au (oz) | E1: Inf. Au (oz) | F1: Assayed Au (oz) | G1: Mea. Ag (oz) | H1: Mea. Ag (oz) | I1: Mea. Ag (oz) | J1: Assayed Ag (oz) | K1: Ag->Au (oz) | L1: TTL Assayed Au (oz) | M1: Auth. Au (oz) | N1: Tripartite Level | O1: OCR Reserve (oz) | P1: Lifetime Release (oz) | Q1: Year 1 Unlock (oz) | R1: Liquidity Allocation (oz) | S1: Unitization Fee Pool (oz) | T1: Admin Units Pool (oz) | U1: Yearly Admin Fee (oz) | V1: Yearly Unitization Fee | W1: Yearly Unlock (oz) | X1: Grantor Comp ($) | Y1: Grantor Comp (oz) | Z1: Grantor Comp (%) | AA1: Comp Per Ounce | AB1: Lifetime Release ($) | AC1: 1st Year Release ($) | AD1: Yearly Release ($) | AE1: 1031 Allocation | AF1: Token Allocation | AG1: Supply Sales | AH1: 1st Yr Monthly Token Sales From Trusts | AI1: Monthly Sales from Trusts | AJ1: Total Yearly Fees (oz) | AK1: Yearly Reg Fee ($) | AL1: Yearly Release Fees ($) | AM1: Total Yearly Fees ($)
A2: Courbet Mine | B2: Dec '25 | C2: 0 | D2: 0 | E2: 46310 | F2: =sum(C2:E2) | G2: 0 | H2: 0 | I2: 229600 | J2: =sum(G2:I2) | K2: =J2/Inputs!B13 | L2: =F2+K2 | M2: =(C2*Inputs!B20)+(D2*Inputs!B21)+(E2*Inputs!B22)+(K2*Inputs!B22) | N2: Mineral + Bio + Social Estate | O2: =M2-P2 | P2: =M2 * VALUE(SUBSTITUTE(VLOOKUP(N2, TTFconfig!A2:E4, 3, FALSE),, "")) | Q2: =M2 * VALUE(SUBSTITUTE(VLOOKUP(N2, TTFconfig!A2:E4, 4, FALSE),, "")) | R2: =M2*Inputs!$B$27 | S2: =M2*Inputs!$B$26 | T2: =M2*(Inputs!$B$25*50) | U2: =M2*Inputs!B25 | V2: =M2*Inputs!B26 | W2: =(P2-Q2-R2-S2-T2-Y2) / VALUE(SUBSTITUTE(VLOOKUP(N2, TTFconfig!A2:E4, 5, FALSE),, "")) | X2: 750000 | Y2: =X2/Inputs!$B$10 | Z2: =Y2/M2 | AA2: =X2/L2 | AB2: =P2*Inputs!B10 | AC2: =Q2*Inputs!B10 | AD2: =W2*Inputs!B10 | AE2: 1 | AF2: =1-AE2 | AG2: Aggressive sales | AH2: =(Q2-'Resource Supply (5yr)'!G10) * AF2 * VALUE(SUBSTITUTE(VLOOKUP(AG2, Inputs!A32:B34, 2, FALSE),, ""))/12 | AI2: =W2 * VALUE(SUBSTITUTE(VLOOKUP(AG2, Inputs!A32:B34, 2, FALSE),, ""))/12 | AJ2: =U2+#REF! | AM2: =AJ2*Inputs!B10
A3: Mine 2 | B3: Jan '26 | C3: 0 | D3: 150000 | E3: 200000 | F3: =sum(C3:E3) | M3: =(C3*Inputs!B20)+(D3*Inputs!B21)+(E3*Inputs!B22) | N3: Mineral + Bio Estate | O3: =M3-P3 | P3: =M3 * VALUE(SUBSTITUTE(VLOOKUP(N3, TTFconfig!A2:E4, 3, FALSE),, "")) | Q3: =M3 * VALUE(SUBSTITUTE(VLOOKUP(N3, TTFconfig!A2:E4, 4, FALSE),, "")) | R3: =M3*Inputs!$B$27 | S3: =M3*Inputs!$B$26 | T3: =M3*(Inputs!$B$25*50) | U3: =M3*Inputs!B25 | V3: =(M3*Inputs!$B$26) / VALUE(SUBSTITUTE(VLOOKUP(N3, TTFconfig!A2:E4, 5, FALSE),, "")) | W3: =(P3-Q3-R3-S3-T3-Y3) / VALUE(SUBSTITUTE(VLOOKUP(N3, TTFconfig!A2:E4, 5, FALSE),, "")) | Y3: =X3/Inputs!$B$10 | AB3: =P3*Inputs!B10 | AC3: =Q3*Inputs!B10 | AD3: =W3*Inputs!B10 | AE3: 0.5 | AF3: =1-AE3 | AG3: Aggressive sales | AH3: =(Q3-'Resource Supply (5yr)'!G10) * AF3 * VALUE(SUBSTITUTE(VLOOKUP(AG3, Inputs!A32:B34, 2, FALSE),, ""))/12 | AI3: =W3 * VALUE(SUBSTITUTE(VLOOKUP(AG3, Inputs!A32:B34, 2, FALSE),, ""))/12 | AJ3: =U3+#REF!
A4: Mine 3 | B4: Jan '26 | C4: 100000 | D4: 800000 | E4: 100000 | F4: =sum(C4:E4) | M4: =(C4*Inputs!B20)+(D4*Inputs!B21)+(E4*Inputs!B22) | N4: Mineral Estate | O4: =M4-P4 | P4: =M4 * VALUE(SUBSTITUTE(VLOOKUP(N4, TTFconfig!A2:E4, 3, FALSE),, "")) | Q4: =M4 * VALUE(SUBSTITUTE(VLOOKUP(N4, TTFconfig!A2:E4, 4, FALSE),, "")) | R4: =M4*Inputs!$B$27 | S4: =M4*Inputs!$B$26 | T4: =M4*(Inputs!$B$25*50) | U4: =M4*Inputs!B25 | V4: =(M4*Inputs!$B$26) / VALUE(SUBSTITUTE(VLOOKUP(N4, TTFconfig!A2:E4, 5, FALSE),, "")) | W4: =(P4-Q4-R4-S4-T4-Y4) / VALUE(SUBSTITUTE(VLOOKUP(N3, TTFconfig!A2:E4, 5, FALSE),, "")) | Y4: =X4/Inputs!$B$10 | AB4: =P4*Inputs!B10 | AC4: =Q4*Inputs!B10 | AD4: =W4*Inputs!B10 | AE4: 0.5 | AF4: =1-AE4 | AG4: Moderate sales | AH4: =(Q4-'Resource Supply (5yr)'!G10) *AF4 * VALUE(SUBSTITUTE(VLOOKUP(AG4, Inputs!A32:B34, 2, FALSE),, ""))/12 | AI4: =W4 * VALUE(SUBSTITUTE(VLOOKUP(AG4, Inputs!A32:B34, 2, FALSE),, ""))/12 | AJ4: =U4+#REF!
A5: Mine 4 | B5: Apr '26 | C5: 25000 | D5: 250000 | E5: 50000 | F5: =sum(C5:E5) | M5: =(C5*Inputs!B20)+(D5*Inputs!B21)+(E5*Inputs!B22) | N5: Mineral + Bio Estate | O5: =M5-P5 | P5: =M5 * VALUE(SUBSTITUTE(VLOOKUP(N5, TTFconfig!A2:E4, 3, FALSE),, "")) | Q5: =M5 * VALUE(SUBSTITUTE(VLOOKUP(N5, TTFconfig!A2:E4, 4, FALSE),, "")) | R5: =M5*Inputs!$B$27 | S5: =M5*Inputs!$B$26 | T5: =M5*(Inputs!$B$25*50) | U5: =M5*Inputs!B25 | V5: =(M5*Inputs!$B$26) / VALUE(SUBSTITUTE(VLOOKUP(N5, TTFconfig!A2:E4, 5, FALSE),, "")) | W5: =(P5-Q5-R5-S5-T5-Y5) / VALUE(SUBSTITUTE(VLOOKUP(N5, TTFconfig!A2:E4, 5, FALSE),, "")) | Y5: =X5/Inputs!$B$10 | AB5: =P5*Inputs!B10 | AC5: =Q5*Inputs!B10 | AD5: =W5*Inputs!B10 | AE5: 0.5 | AF5: =1-AE5 | AG5: Moderate sales | AH5: =(Q5-'Resource Supply (5yr)'!G10) * AF5 * VALUE(SUBSTITUTE(VLOOKUP(AG5, Inputs!A32:B34, 2, FALSE),, ""))/12 | AI5: =W5 * VALUE(SUBSTITUTE(VLOOKUP(AG5, Inputs!A32:B34, 2, FALSE),, ""))/12 | AJ5: =U5+#REF!
A6: Mine 5 | B6: Jul '26 | C6: 50000 | D6: 490000 | E6: 170000 | F6: =sum(C6:E6) | M6: =(C6*Inputs!B20)+(D6*Inputs!B21)+(E6*Inputs!B22) | N6: Mineral + Bio + Social Estate | O6: =M6-P6 | P6: =M6 * VALUE(SUBSTITUTE(VLOOKUP(N6, TTFconfig!A2:E4, 3, FALSE),, "")) | Q6: =M6 * VALUE(SUBSTITUTE(VLOOKUP(N6, TTFconfig!A2:E4, 4, FALSE),, "")) | R6: =M6*Inputs!$B$27 | S6: =M6*Inputs!$B$26 | T6: =M6*(Inputs!$B$25*50) | U6: =M6*Inputs!B25 | V6: =(M6*Inputs!$B$26) / VALUE(SUBSTITUTE(VLOOKUP(N6, TTFconfig!A2:E4, 5, FALSE),, "")) | W6: =(P6-Q6-R6-S6-T6-Y6) / VALUE(SUBSTITUTE(VLOOKUP(N6, TTFconfig!A2:E4, 5, FALSE),, "")) | Y6: =X6/Inputs!$B$10 | AB6: =P6*Inputs!B10 | AC6: =Q6*Inputs!B9 | AD6: =W6*Inputs!B10 | AE6: 0.5 | AF6: =1-AE6 | AG6: Moderate sales | AH6: =(Q6-'Resource Supply (5yr)'!G10) * AF6 * VALUE(SUBSTITUTE(VLOOKUP(AG6, Inputs!A32:B34, 2, FALSE),, ""))/12 | AI6: =W6 * VALUE(SUBSTITUTE(VLOOKUP(AG6, Inputs!A32:B34, 2, FALSE),, ""))/12 | AJ6: =U6+#REF!
A7: Mine 6 | B7: Dec '26 | C7: 10000 | D7: 50000 | E7: 40000 | F7: =sum(C7:E7) | M7: =(C7*Inputs!B20)+(D7*Inputs!B21)+(E7*Inputs!B22) | N7: Mineral + Bio + Social Estate | O7: =M7-P7 | P7: =M7 * VALUE(SUBSTITUTE(VLOOKUP(N7, TTFconfig!A2:E4, 3, FALSE),, "")) | Q7: =M7 * VALUE(SUBSTITUTE(VLOOKUP(N7, TTFconfig!A2:E4, 4, FALSE),, "")) | R7: =M7*Inputs!$B$27 | S7: =M7*Inputs!$B$26 | T7: =M7*(Inputs!$B$25*50) | U7: =M7*Inputs!B25 | V7: =(M7*Inputs!$B$26) / VALUE(SUBSTITUTE(VLOOKUP(N7, TTFconfig!A2:E4, 5, FALSE),, "")) | W7: =(P7-Q7-R7-S7-T7-Y7) / VALUE(SUBSTITUTE(VLOOKUP(N7, TTFconfig!A2:E4, 5, FALSE),, "")) | Y7: =X7/Inputs!$B$10 | AB7: =P7*Inputs!B10 | AC7: =Q7*Inputs!B10 | AD7: =W7*Inputs!B10 | AE7: 0.5 | AF7: =1-AE7 | AG7: Moderate sales | AH7: =(Q7-'Resource Supply (5yr)'!G10) *AF7* VALUE(SUBSTITUTE(VLOOKUP(AG7, Inputs!A32:B34, 2, FALSE),, ""))/12 | AI7: =W7 * VALUE(SUBSTITUTE(VLOOKUP(AG7, Inputs!A32:B34, 2, FALSE),, ""))/12 | AJ7: =U7+#REF!
A8: Mine 7 | B8: Mar '27 | C8: 25000 | D8: 100000 | E8: 50000 | F8: =sum(C8:E8) | M8: =(C8*Inputs!B20)+(D8*Inputs!B21)+(E8*Inputs!B22) | N8: Mineral Estate | O8: =M8-P8 | P8: =M8 * VALUE(SUBSTITUTE(VLOOKUP(N8, TTFconfig!A2:E4, 3, FALSE),, "")) | Q8: =M8 * VALUE(SUBSTITUTE(VLOOKUP(N8, TTFconfig!A2:E4, 4, FALSE),, "")) | R8: =M8*Inputs!$B$27 | S8: =M8*Inputs!$B$26 | T8: =M8*(Inputs!$B$25*50) | U8: =M8*Inputs!B25 | V8: =(M8*Inputs!$B$26) / VALUE(SUBSTITUTE(VLOOKUP(N8, TTFconfig!A2:E4, 5, FALSE),, "")) | W8: =(P8-Q8-R8-S8-T8-Y8) / VALUE(SUBSTITUTE(VLOOKUP(N8, TTFconfig!A2:E4, 5, FALSE),, "")) | Y8: =X8/Inputs!$B$10 | AB8: =P8*Inputs!B10 | AC8: =Q8*Inputs!B10 | AD8: =W8*Inputs!B10 | AE8: 0.5 | AF8: =1-AE8 | AG8: Moderate sales | AH8: =(Q8-'Resource Supply (5yr)'!G10) *AF8 * VALUE(SUBSTITUTE(VLOOKUP(AG8, Inputs!A32:B34, 2, FALSE),, ""))/12 | AI8: =W8 * VALUE(SUBSTITUTE(VLOOKUP(AG8, Inputs!A32:B34, 2, FALSE),, ""))/12 | AJ8: =U8+#REF!
A9: Mine 8 | B9: Jun '27 | C9: 200000 | D9: 1000000 | E9: 100000 | F9: =sum(C9:E9) | M9: =(C9*Inputs!B20)+(D9*Inputs!B21)+(E9*Inputs!B22) | N9: Mineral Estate | O9: =M9-P9 | P9: =M9 * VALUE(SUBSTITUTE(VLOOKUP(N9, TTFconfig!A2:E4, 3, FALSE),, "")) | Q9: =M9 * VALUE(SUBSTITUTE(VLOOKUP(N9, TTFconfig!A2:E4, 4, FALSE),, "")) | R9: =M9*Inputs!$B$27 | S9: =M9*Inputs!$B$26 | T9: =M9*(Inputs!$B$25*50) | U9: =M9*Inputs!B25 | V9: =(M9*Inputs!$B$26) / VALUE(SUBSTITUTE(VLOOKUP(N9, TTFconfig!A2:E4, 5, FALSE),, "")) | W9: =(P9-Q9-R9-S9-T9-Y9) / VALUE(SUBSTITUTE(VLOOKUP(N9, TTFconfig!A2:E4, 5, FALSE),, "")) | Y9: =X9/Inputs!$B$10 | AB9: =P9*Inputs!B10 | AC9: =Q9*Inputs!B10 | AD9: =W9*Inputs!B10 | AE9: 0.5 | AF9: =1-AE9 | AG9: Moderate sales | AH9: =(Q9-'Resource Supply (5yr)'!G10) * AF9 * VALUE(SUBSTITUTE(VLOOKUP(AG9, Inputs!A32:B34, 2, FALSE),, ""))/12 | AI9: =W9 * VALUE(SUBSTITUTE(VLOOKUP(AG9, Inputs!A32:B34, 2, FALSE),, ""))/12 | AJ9: =U9+#REF!
A10: Mine 9 | B10: Aug '27 | C10: 50000 | D10: 490000 | E10: 170000 | F10: =sum(C10:E10) | M10: =(C10*Inputs!B20)+(D10*Inputs!B21)+(E10*Inputs!B22) | N10: Mineral + Bio Estate | O10: =M10-P10 | P10: =M10 * VALUE(SUBSTITUTE(VLOOKUP(N10, TTFconfig!A2:E4, 3, FALSE),, "")) | Q10: =M10 * VALUE(SUBSTITUTE(VLOOKUP(N10, TTFconfig!A2:E4, 4, FALSE),, "")) | R10: =M10*Inputs!$B$27 | S10: =M10*Inputs!$B$26 | T10: =M10*(Inputs!$B$25*50) | U10: =M10*Inputs!B25 | V10: =(M10*Inputs!$B$26) / VALUE(SUBSTITUTE(VLOOKUP(N10, TTFconfig!A2:E4, 5, FALSE),, "")) | W10: =(P10-Q10-R10-S10-T10-Y10) / VALUE(SUBSTITUTE(VLOOKUP(N10, TTFconfig!A2:E4, 5, FALSE),, "")) | Y10: =X10/Inputs!$B$10 | AB10: =P10*Inputs!B9 | AC10: =Q10*Inputs!B10 | AD10: =W10*Inputs!B10 | AE10: 0.5 | AF10: =1-AE10 | AG10: Moderate sales | AH10: =(Q10-'Resource Supply (5yr)'!G10) * AF10 * VALUE(SUBSTITUTE(VLOOKUP(AG10, Inputs!A32:B34, 2, FALSE),, ""))/12 | AI10: =W10 * VALUE(SUBSTITUTE(VLOOKUP(AG10, Inputs!A32:B34, 2, FALSE),, ""))/12 | AJ10: =U10+#REF!
A11: Mine 10 | B11: Feb '28 | C11: 200000 | D11: 1000000 | E11: 100000 | F11: =sum(C11:E11) | M11: =(C11*Inputs!B20)+(D11*Inputs!B21)+(E11*Inputs!B22) | N11: Mineral Estate | O11: =M11-P11 | P11: =M11 * VALUE(SUBSTITUTE(VLOOKUP(N11, TTFconfig!A2:E4, 3, FALSE),, "")) | Q11: =M11 * VALUE(SUBSTITUTE(VLOOKUP(N11, TTFconfig!A2:E4, 4, FALSE),, "")) | R11: =M11*Inputs!$B$27 | S11: =M11*Inputs!$B$26 | T11: =M11*(Inputs!$B$25*50) | U11: =M11*Inputs!B25 | V11: =(M11*Inputs!$B$26) / VALUE(SUBSTITUTE(VLOOKUP(N11, TTFconfig!A2:E4, 5, FALSE),, "")) | W11: =(P11-Q11-R11-S11-T11-Y11) / VALUE(SUBSTITUTE(VLOOKUP(N11, TTFconfig!A2:E4, 5, FALSE),, "")) | Y11: =X11/Inputs!$B$10 | AB11: =P11*Inputs!B10 | AC11: =Q11*Inputs!B10 | AD11: =W11*Inputs!B10 | AE11: 0.5 | AF11: =1-AE11 | AG11: Conservative sales | AH11: =(Q11-'Resource Supply (5yr)'!G10) * AF11 * VALUE(SUBSTITUTE(VLOOKUP(AG11, Inputs!A32:B34, 2, FALSE),, ""))/12 | AI11: =W11 * VALUE(SUBSTITUTE(VLOOKUP(AG11, Inputs!A32:B34, 2, FALSE),, ""))/12 | AJ11: =U11+#REF!
A12: Mine 11 | B12: May '28 | C12: 50000 | D12: 490000 | E12: 170000 | F12: =sum(C12:E12) | M12: =(C12*Inputs!B20)+(D12*Inputs!B21)+(E12*Inputs!B22) | N12: Mineral + Bio Estate | O12: =M12-P12 | P12: =M12 * VALUE(SUBSTITUTE(VLOOKUP(N12, TTFconfig!A2:E4, 3, FALSE),, "")) | Q12: =M12 * VALUE(SUBSTITUTE(VLOOKUP(N12, TTFconfig!A2:E4, 4, FALSE),, "")) | R12: =M12*Inputs!$B$27 | S12: =M12*Inputs!$B$26 | T12: =M12*(Inputs!$B$25*50) | U12: =M12*Inputs!B25 | V12: =(M12*Inputs!$B$26) / VALUE(SUBSTITUTE(VLOOKUP(N12, TTFconfig!A2:E4, 5, FALSE),, "")) | W12: =(P12-Q12-R12-S12-T12-Y12) / VALUE(SUBSTITUTE(VLOOKUP(N12, TTFconfig!A2:E4, 5, FALSE),, "")) | Y12: =X12/Inputs!$B$10 | AB12: =P12*Inputs!B10 | AC12: =Q12*Inputs!B10 | AD12: =W12*Inputs!B10 | AE12: 0.5 | AF12: =1-AE12 | AG12: Conservative sales | AH12: =(Q12-'Resource Supply (5yr)'!G10) * AF12 * VALUE(SUBSTITUTE(VLOOKUP(AG12, Inputs!A32:B34, 2, FALSE),, ""))/12 | AI12: =W12 * VALUE(SUBSTITUTE(VLOOKUP(AG12, Inputs!A32:B34, 2, FALSE),, ""))/12 | AJ12: =U12+#REF!
A13: Mine 12 | B13: Oct '28 | C13: 50000 | D13: 490000 | E13: 170000 | F13: =sum(C13:E13) | M13: =(C13*Inputs!B20)+(D13*Inputs!B21)+(E13*Inputs!B22) | N13: Mineral + Bio + Social Estate | O13: =M13-P13 | P13: =M13 * VALUE(SUBSTITUTE(VLOOKUP(N13, TTFconfig!A2:E4, 3, FALSE),, "")) | Q13: =M13 * VALUE(SUBSTITUTE(VLOOKUP(N13, TTFconfig!A2:E4, 4, FALSE),, "")) | R13: =M13*Inputs!$B$27 | S13: =M13*Inputs!$B$26 | T13: =M13*(Inputs!$B$25*50) | U13: =M13*Inputs!B25 | V13: =(M13*Inputs!$B$26) / VALUE(SUBSTITUTE(VLOOKUP(N13, TTFconfig!A2:E4, 5, FALSE),, "")) | W13: =(P13-Q13-R13-S13-T13-Y13) / VALUE(SUBSTITUTE(VLOOKUP(N13, TTFconfig!A2:E4, 5, FALSE),, "")) | Y13: =X13/Inputs!$B$10 | AB13: =P13*Inputs!B10 | AC13: =Q13*Inputs!B10 | AD13: =W13*Inputs!B10 | AE13: 0.5 | AF13: =1-AE13 | AG13: Conservative sales | AH13: =(Q13-'Resource Supply (5yr)'!G10) * AF13 * VALUE(SUBSTITUTE(VLOOKUP(AG13, Inputs!A32:B34, 2, FALSE),, ""))/12 | AI13: =W13 * VALUE(SUBSTITUTE(VLOOKUP(AG13, Inputs!A32:B34, 2, FALSE),, ""))/12 | AJ13: =U13+#REF!
A14: Totals | C14: =sum(C2:C13) | D14: =sum(D2:D13) | E14: =sum(E2:E13) | F14: =sum(C14:E14) | M14: =SUM(M2:M13) | P14: =SUM(P2:P13) | U14: =SUM(U2:U13) | W14: =SUM(W2:W13) | AB14: =SUM(AB2:AB13) | AD14: =SUM(AD2:AD13) | AJ14: =SUM(AJ2:AJ13)
G22: 20460 | H22: 115880
G23: 25850 | H23: 113720
G24: =sum(G22:G23) | H24: =sum(H22:H23)
G30: =sum(G27+I27)
L32: 228830 | M32: 145400
L34: =sum(L32,M32)
G37: =56*3300

Sheet Resource Supply (5yr)
A1: Resource Supply (5yr) | B1: Jan '25 | C1: Feb '25 | D1: Mar '25 | E1: Apr '25 | F1: May '25 | G1: Jun '25 | H1: Jul '25 | I1: Aug '25 | J1: Sep '25 | K1: Oct '25 | L1: Nov '25 | M1: Dec '25 | N1: Jan '26 | O1: Feb '26 | P1: Mar '26 | Q1: Apr '26 | R1: May '26 | S1: Jun '26 | T1: Jul '26 | U1: Aug '26 | V1: Sep '26 | W1: Oct '26 | X1: Nov '26 | Y1: Dec '26 | Z1: Jan '27 | AA1: Feb '27 | AB1: Mar '27 | AC1: Apr '27 | AD1: May '27 | AE1: Jun '27 | AF1: Jul '27 | AG1: Aug '27 | AH1: Sep '27 | AI1: Oct '27 | AJ1: Nov '27 | AK1: Dec '27 | AL1: Jan '28 | AM1: Feb '28 | AN1: Mar '28 | AO1: Apr '28 | AP1: May '28 | AQ1: Jun '28 | AR1: Jul '28 | AS1: Aug '28 | AT1: Sep '28 | AU1: Oct '28 | AV1: Nov '28 | AW1: Dec '28 | AX1: Jan '29 | AY1: Feb '29 | AZ1: Mar '29 | BA1: Apr '29 | BB1: May '29 | BC1: Jun '29 | BD1: Jul '29 | BE1: Aug '29 | BF1: Sep '29 | BG1: Oct '29 | BH1: Nov '29 | BI1: Dec '29
A2: Gold Resource Supply
A3: # of mines brought online | B3: 0 | C3: 0 | D3: 0 | E3: 0 | F3: 0 | G3: 0 | H3: 0 | I3: 0 | J3: 1 | K3: 0 | L3: 1 | M3: 0 | N3: 1 | O3: 0 | P3: 0 | Q3: 1 | R3: 0 | S3: 0 | T3: 1 | U3: 0 | V3: 0 | W3: 0 | X3: 0 | Y3: 1 | Z3: 0 | AA3: 0 | AB3: 1 | AC3: 0 | AD3: 0 | AE3: 1 | AF3: 0 | AG3: 1 | AH3: 0 | AI3: 0 | AJ3: 0 | AK3: 0 | AL3: 0 | AM3: 1 | AN3: 0 | AO3: 0 | AP3: 1 | AQ3: 0 | AR3: 0 | AS3: 0 | AT3: 0 | AU3: 1 | AV3: 0 | AW3: 0 | AX3: 0 | AY3: 0 | AZ3: 0 | BA3: 0 | BB3: 0 | BC3: 0 | BD3: 0 | BE3: 0 | BF3: 0 | BG3: 0 | BH3: 0 | BI3: 0
A4: Registered Resources (oz) | B4: 0 | C4: 0 | D4: 0 | E4: 0 | F4: 0 | G4: 0 | H4: 0 | I4: 0 | J4: ='Mine Inventory'!F2 | K4: 0 | L4: ='Mine Inventory'!F3 | M4: 0 | N4: ='Mine Inventory'!F4 | O4: 0 | P4: 0 | Q4: ='Mine Inventory'!F5 | R4: 0 | S4: 0 | T4: ='Mine Inventory'!F6 | Y4: ='Mine Inventory'!F7 | Z4: 0 | AA4: 0 | AB4: ='Mine Inventory'!F8 | AC4: 0 | AD4: 0 | AE4: ='Mine Inventory'!F9 | AF4: 0 | AG4: ='Mine Inventory'!F10 | AH4: 0 | AI4: 0 | AJ4: 0 | AK4: 0 | AL4: 0 | AM4: ='Mine Inventory'!F11 | AN4: 0 | AO4: 0 | AP4: ='Mine Inventory'!F12 | AQ4: 0 | AR4: 0 | AS4: 0 | AT4: 0 | AU4: ='Mine Inventory'!F13 | AV4: 0 | AW4: 0 | AX4: 0 | AY4: 0 | AZ4: 0 | BA4: 0 | BB4: 0 | BC4: 0 | BD4: 0 | BE4: 0 | BF4: 0 | BG4: 0 | BH4: 0 | BI4: 0
A5: Authorized Resources (oz) | B5: 0 | C5: 0 | D5: 0 | E5: 0 | F5: 0 | G5: 0 | H5: 0 | I5: 0 | J5: ='Mine Inventory'!M2 | K5: 0 | L5: ='Mine Inventory'!M3 | M5: 0 | N5: ='Mine Inventory'!M4 | O5: 0 | P5: 0 | Q5: ='Mine Inventory'!M5 | R5: 0 | S5: 0 | T5: ='Mine Inventory'!M6 | U5: 0 | V5: 0 | W5: 0 | X5: 0 | Y5: ='Mine Inventory'!M7 | Z5: 0 | AA5: 0 | AB5: ='Mine Inventory'!M8 | AC5: 0 | AD5: 0 | AE5: ='Mine Inventory'!M9 | AF5: 0 | AG5: ='Mine Inventory'!M10 | AH5: 0 | AI5: 0 | AJ5: 0 | AK5: 0 | AL5: 0 | AM5: ='Mine Inventory'!M11 | AN5: 0 | AO5: 0 | AP5: ='Mine Inventory'!M12 | AQ5: 0 | AR5: 0 | AS5: 0 | AT5: 0 | AU5: ='Mine Inventory'!M13 | AV5: 0 | AW5: 0 | AX5: 0 | AY5: 0 | AZ5: 0 | BA5: 0 | BB5: 0 | BC5: 0 | BD5: 0 | BE5: 0 | BF5: 0 | BG5: 0 | BH5: 0 | BI5: 0
A6: Releasable Resources (oz) | B6: 0 | C6: 0 | D6: 0 | E6: 0 | F6: 0 | G6: 0 | H6: 0 | I6: 0 | J6: ='Mine Inventory'!P2 | K6: 0 | L6: ='Mine Inventory'!$P$3 | M6: 0 | N6: ='Mine Inventory'!P4 | O6: 0 | P6: 0 | Q6: ='Mine Inventory'!P5 | R6: 0 | S6: 0 | T6: ='Mine Inventory'!P6 | U6: 0 | V6: 0 | W6: 0 | X6: 0 | Y6: ='Mine Inventory'!P7 | Z6: 0 | AA6: 0 | AB6: ='Mine Inventory'!P8 | AC6: 0 | AD6: 0 | AE6: ='Mine Inventory'!P9 | AF6: 0 | AG6: ='Mine Inventory'!P10 | AH6: 0 | AI6: 0 | AJ6: 0 | AK6: 0 | AL6: 0 | AM6: ='Mine Inventory'!P11 | AN6: 0 | AO6: 0 | AP6: ='Mine Inventory'!P12 | AQ6: 0 | AR6: 0 | AS6: 0 | AT6: 0 | AU6: ='Mine Inventory'!P13 | AV6: 0 | AW6: 0 | AX6: 0 | AY6: 0 | AZ6: 0 | BA6: 0 | BB6: 0 | BC6: 0 | BD6: 0 | BE6: 0 | BF6: 0 | BG6: 0 | BH6: 0 | BI6: 0
A7: Unlocked Resources (oz) | B7: 0 | C7: 0 | D7: 0 | E7: 0 | F7: 0 | G7: 0 | H7: =(H5*'Release Terms'!C2)*'Release Terms'!E2 | I7: 0 | J7: ='Mine Inventory'!Q2 | K7: 0 | L7: ='Mine Inventory'!$Q$3 | M7: 0 | N7: ='Mine Inventory'!Q4 | O7: 0 | P7: 0 | Q7: ='Mine Inventory'!Q5 | R7: 0 | S7: 0 | T7: ='Mine Inventory'!Q6 | U7: 0 | V7: ='Mine Inventory'!W2 | W7: 0 | X7: ='Mine Inventory'!$W$3 | Y7: ='Mine Inventory'!Q7 | Z7: ='Mine Inventory'!$W$4 | AA7: 0 | AB7: ='Mine Inventory'!Q8 | AC7: ='Mine Inventory'!$W$5 | AD7: 0 | AE7: ='Mine Inventory'!Q9 | AF7: ='Mine Inventory'!$W$6 | AG7: ='Mine Inventory'!Q10 | AH7: ='Mine Inventory'!$W$2 | AI7: 0 | AJ7: ='Mine Inventory'!$W$3 | AK7: ='Mine Inventory'!$W$7 | AL7: ='Mine Inventory'!$W$4 | AM7: ='Mine Inventory'!Q11 | AN7: ='Mine Inventory'!$W$8 | AO7: ='Mine Inventory'!$W$5 | AP7: ='Mine Inventory'!Q12 | AQ7: ='Mine Inventory'!$W$9 | AR7: ='Mine Inventory'!$W$6 | AS7: ='Mine Inventory'!$W$10 | AT7: ='Mine Inventory'!$W$2 | AU7: ='Mine Inventory'!Q13 | AV7: ='Mine Inventory'!$W$3 | AW7: ='Mine Inventory'!$W$7 | AX7: ='Mine Inventory'!$W$4 | AY7: ='Mine Inventory'!$W$11 | AZ7: ='Mine Inventory'!$W$8 | BA7: ='Mine Inventory'!$W$5 | BB7: ='Mine Inventory'!$W$12 | BC7: ='Mine Inventory'!$W$9 | BD7: ='Mine Inventory'!$W$6 | BE7: ='Mine Inventory'!$W$10 | BF7: ='Mine Inventory'!$W$2 | BG7: ='Mine Inventory'!$W$13 | BH7: ='Mine Inventory'!$W$3 | BI7: ='Mine Inventory'!$W$7
A8: Unitization Fees (oz) | B8: 0 | C8: 0 | D8: 0 | E8: 0 | F8: 0 | G8: =(G5*Inputs!B25) | H8: =(H5*Inputs!B25)/'Release Terms'!D2 | I8: 0 | J8: =(J5*0.5%) | K8: 0 | L8: =(L5*Inputs!$B$25) | M8: 0 | N8: =(N5*Inputs!$B$25) | O8: 0 | P8: 0 | Q8: ='Mine Inventory'!U5 | R8: 0 | S8: 0 | T8: ='Mine Inventory'!U6 | U8: 0 | V8: 0 | W8: 0 | X8: ='Mine Inventory'!$U$2 | Y8: ='Mine Inventory'!U7 | Z8: ='Mine Inventory'!$U$4 | AA8: 0 | AB8: ='Mine Inventory'!U8 | AC8: ='Mine Inventory'!$U$5 | AD8: 0 | AE8: ='Mine Inventory'!$U$9 | AF8: ='Mine Inventory'!$U$6 | AG8: ='Mine Inventory'!U10 | AH8: 0 | AI8: 0 | AJ8: ='Mine Inventory'!$U$2 | AK8: ='Mine Inventory'!$U$7 | AL8: ='Mine Inventory'!$U$4 | AM8: ='Mine Inventory'!U11 | AN8: ='Mine Inventory'!$U$8 | AO8: ='Mine Inventory'!$U$5 | AP8: ='Mine Inventory'!U12 | AQ8: ='Mine Inventory'!$U$9 | AR8: ='Mine Inventory'!$U$6 | AS8: ='Mine Inventory'!$U$10 | AT8: 0 | AU8: ='Mine Inventory'!U13 | AV8: ='Mine Inventory'!$U$2 | AW8: ='Mine Inventory'!$U$7 | AX8: ='Mine Inventory'!$U$4 | AY8: ='Mine Inventory'!$U$11 | AZ8: ='Mine Inventory'!$U$8 | BA8: ='Mine Inventory'!$U$5 | BB8: ='Mine Inventory'!$U$12 | BC8: ='Mine Inventory'!$U$9 | BD8: ='Mine Inventory'!$U$6 | BE8: ='Mine Inventory'!$U$10 | BF8: 0 | BG8: ='Mine Inventory'!$U$13 | BH8: ='Mine Inventory'!$U$2 | BI8: ='Mine Inventory'!$U$7
A9: Available 1031 units (oz) | B9: 0 | C9: 0 | D9: 0 | E9: 0 | F9: 0 | G9: 0 | H9: 0 | I9: 0 | J9: =(J7)*'Mine Inventory'!AE2 | K9: 0 | L9: =L7*'Mine Inventory'!$AE$3 | M9: 0 | N9: =N7*'Mine Inventory'!AE4 | O9: 0 | P9: 0 | Q9: =Q7*'Mine Inventory'!AE5 | R9: 0 | S9: 0 | T9: =T7*'Mine Inventory'!AE6 | U9: 0 | V9: =V7*'Mine Inventory'!$AE$2 | W9: 0 | X9: =X7*'Mine Inventory'!$AE$3 | Y9: =Y7*'Mine Inventory'!AE7 | Z9: =Z7*'Mine Inventory'!$AE$4 | AB9: =AB7*'Mine Inventory'!AE8 | AC9: =AC7*'Mine Inventory'!$AE$5 | AE9: =AE7*'Mine Inventory'!AE9 | AF9: =AF7*'Mine Inventory'!$AE$6 | AG9: =AG7*'Mine Inventory'!AE10 | AH9: =AH7*'Mine Inventory'!$AE$2 | AJ9: =AJ7*'Mine Inventory'!$AE$3 | AK9: =AK7*'Mine Inventory'!$AE$7 | AL9: =AL7*'Mine Inventory'!$AE$4 | AM9: =AM7*'Mine Inventory'!AE11 | AN9: =AN7*'Mine Inventory'!$AE$8 | AO9: =AO7*'Mine Inventory'!$AE$5 | AP9: =AP7*'Mine Inventory'!AE12 | AQ9: =AQ7*'Mine Inventory'!$AE$9 | AR9: =AR7*'Mine Inventory'!$AE$6 | AS9: =AS7*'Mine Inventory'!$AE$10 | AT9: =AT7*'Mine Inventory'!$AE$2 | AU9: =AU7*'Mine Inventory'!AE13 | AV9: =AV7*'Mine Inventory'!$AE$3 | AW9: =AW7*'Mine Inventory'!$AE$7 | AX9: =AX7*'Mine Inventory'!$AE$4 | AY9: =AY7*'Mine Inventory'!$AE$11 | AZ9: =AZ7*'Mine Inventory'!$AE$8 | BA9: =BA7*'Mine Inventory'!$AE$5 | BB9: =BB7*'Mine Inventory'!$AE$12 | BC9: =BC7*'Mine Inventory'!$AE$9 | BD9: =BD7*'Mine Inventory'!$AE$6 | BE9: =BE7*'Mine Inventory'!$AE$10 | BF9: =BF7*'Mine Inventory'!$AE$2 | BG9: =BG7*'Mine Inventory'!$AE$13 | BH9: =BH7*'Mine Inventory'!$AE$3 | BI9: =BI7*'Mine Inventory'!$AE$7
A10: Admin Fees (oz) | B10: 0 | C10: 0 | D10: 0 | E10: 0 | F10: 0 | G10: =G7*Inputs!B26 | H10: =H7*Inputs!B26 | I10: 0 | J10: =J7*Inputs!$B$26 | K10: =K7*Inputs!$B$26 | L10: =L7*Inputs!$B$26 | M10: =M7*Inputs!$B$26 | N10: =N9*Inputs!$B$26 | O10: =O9*Inputs!$B$26 | P10: =P9*Inputs!$B$26 | Q10: =Q9*Inputs!$B$26 | R10: =R9*Inputs!$B$26 | S10: =S9*Inputs!$B$26 | T10: =T9*Inputs!$B$26 | U10: =U9*Inputs!$B$26 | ... BI10: =BI9*Inputs!$B$26
A11: RGT Liquidity Fee (oz) | B11: 0 | C11: 0 | D11: 0 | E11: 0 | F11: 0 | G11: 0 | H11: 0 | I11: 0 | J11: ='Mine Inventory'!R2 | K11: 0 | L11: ='Mine Inventory'!R3 | M11: 0 | N11: ='Mine Inventory'!R4 | O11: 0 | P11: 0 | Q11: ='Mine Inventory'!R5 | R11: 0 | S11: 0 | T11: ='Mine Inventory'!R6 | U11: 0 | V11: 0 | W11: 0 | X11: 0 | Y11: ='Mine Inventory'!R7 | Z11: 0 | AA11: 0 | AB11: ='Mine Inventory'!R8 | AC11: 0 | AD11: 0 | AE11: ='Mine Inventory'!R9 | AF11: 0 | AG11: ='Mine Inventory'!R10 | AH11: 0 | AI11: 0 | AJ11: 0 | AK11: 0 | AL11: 0 | AM11: ='Mine Inventory'!R11 | AN11: 0 | AO11: 0 | AP11: ='Mine Inventory'!R12 | AQ11: 0 | AR11: 0 | AS11: 0 | AT11: 0 | AU11: ='Mine Inventory'!R13 | AV11: 0 | AW11: 0 | AX11: 0 | AY11: 0 | AZ11: 0 | BA11: 0 | BB11: 0 | BC11: 0 | BD11: 0 | BE11: 0 | BF11: 0 | BG11: 0 | BH11: 0 | BI11: 0
A12: New Allocation to RealGold Treasury (oz) | B12: 0 | C12: 0 | D12: 0 | E12: 0 | F12: 0 | G12: 0 | H12: 0 | I12: 0 | J12: =J11 + (J7*'Mine Inventory'!AF2) | K12: 0 | L12: =L11 + (L7*'Mine Inventory'!AF3) | M12: 0 | N12: =N11 + (N7*'Mine Inventory'!AF4) | O12: 0 | P12: 0 | Q12: =Q11 + (Q7*'Mine Inventory'!AF5) | R12: 0 | S12: 0 | T12: =T11 + (T7*'Mine Inventory'!AF6) | U12: 0 | V12: =V7*'Mine Inventory'!$AF$2 | W12: 0 | X12: =X7*'Mine Inventory'!$AF$3 | Y12: =Y11 + (Y7*'Mine Inventory'!AF7) | Z12: =Z7*'Mine Inventory'!$AF$4 | AB12: =AB11 + (AB7*'Mine Inventory'!AF8) | AC12: =AC7*'Mine Inventory'!$AF$5 | AE12: =AE11 + (AE7*'Mine Inventory'!AF9) | AF12: =AF7*'Mine Inventory'!$AF$6 | AG12: =AG11 + (AG7*'Mine Inventory'!AF10) | AH12: =AH7*'Mine Inventory'!$AF$2 | AI12: 0 | AJ12: =AJ7*'Mine Inventory'!$AF$3 | AK12: =AK7*'Mine Inventory'!$AF$7 | AL12: =AL7*'Mine Inventory'!$AF$4 | AM12: =AM11 + (AM7*'Mine Inventory'!AF11) | AN12: =AN7*'Mine Inventory'!$AF$8 | AO12: =AO7*'Mine Inventory'!$AF$5 | AP12: =AP11 + (AP7*'Mine Inventory'!AF12) | AQ12: =AQ7*'Mine Inventory'!$AF$9 | AR12: =AR7*'Mine Inventory'!$AF$6 | AS12: =AS7*'Mine Inventory'!$AF$10 | AT12: =AT7*'Mine Inventory'!$AF$2 | AU12: =AU11 + (AU7*'Mine Inventory'!AF13) | AV12: =AV7*'Mine Inventory'!$AF$3 | AW12: =AW7*'Mine Inventory'!$AF$7 | AX12: =AX7*'Mine Inventory'!$AF$4 | AY12: =AY7*'Mine Inventory'!$AF$10 | AZ12: =AZ7*'Mine Inventory'!$AF$8 | BA12: =BA7*'Mine Inventory'!$AF$5 | BB12: =BB7*'Mine Inventory'!$AF$12 | BC12: =BC7*'Mine Inventory'!$AF$9 | BD12: =BD7*'Mine Inventory'!$AF$6 | BE12: =BE7*'Mine Inventory'!$AF$10 | BF12: =BF7*'Mine Inventory'!$AF$2 | BG12: =BG7*'Mine Inventory'!$AF$13 | BH12: =BH7*'Mine Inventory'!$AF$3 | BI12: =BI7*'Mine Inventory'!$AF$7
A13: RealGold Token Minting Fees (oz) | B13: 0 | C13: 0 | D13: 0 | E13: 0 | F13: 0 | G13: 0 | H13: 0 | I13: 0 | J13: =J12*Inputs!$B$26 | K13: =K12*Inputs!$B$26 | L13: =L12*Inputs!$B$26 | M13: =M12*Inputs!$B$26 | N13: =N12*Inputs!$B$26 | O13: =O12*Inputs!$B$26 | P13: =P12*Inputs!$B$26 | Q13: =Q12*Inputs!$B$26 | ... BI13: =BI12*Inputs!$B$26
A14: Total Admin & Unit Fee Rev RAF (oz) | B14: 0 | C14: 0 | D14: 0 | E14: 0 | F14: 0 | G14: =sum(G8:G12) | H14: =sum(H8:H12) | I14: 0 | J14: =sum(J8+J10) | K14: 0 | L14: =sum(L8+L10) | M14: =sum(M8+M10) | N14: =sum(N8+N10) | O14: =sum(O8+O10) | P14: =sum(P8+P10) | Q14: =sum(Q8+Q10) | R14: =sum(R8+R10) | S14: =sum(S8+S10) | ... V14: =sum(V8+V10) | W14: 0 | X14: =sum(X8+X10) | Y14: =sum(Y8+Y10) | Z14: =sum(Z8+Z10) | AA14: =sum(AA8+AA10) | AB14: =sum(AB8+AB10) | AC14: =sum(AC8+AC10) | AD14: =sum(AD8+AD10) | AE14: =sum(AE8+AE10) | ... BI14: =sum(BI8+BI10)
A15: Allocation to 1031 by Trusts (oz) | B15: 0 | C15: 0 | D15: 0 | E15: 0 | F15: 0 | G15: =(G7-G10)*'Mine Inventory'!AE2 | H15: =(H7-H10)*'Mine Inventory'!AF2 | I15: 0 | J15: =(J9-J10) | K15: =(K9-K10) | L15: =(L9-L10) | M15: =(M9-M10) | N15: =(N9-N10) | O15: =(O9-O10) | P15: =(P9-P10) | Q15: =(Q9-Q10) | ... BI15: =(BI9-BI10)
A16: Allocation to RealGold Treasury by Trusts (oz) | B16: 0 | C16: 0 | D16: 0 | E16: 0 | F16: 0 | G16: 0 | H16: 0 | I16: 0 | J16: =J12-J13 | K16: =K12-K13 | L16: =L12-L13 | M16: =M12-M13 | N16: =N12-N13 | O16: =O12-O13 | P16: =P12-P13 | Q16: =Q12-Q13 | ... BI16: =BI12-BI13
A18: Registered Resources ($) | B18: 0 | C18: 0 | D18: 0 | E18: 0 | F18: 0 | G18: =G4*XAUconfig!G3 | H18: =H4*XAUconfig!H3 | I18: =I4*XAUconfig!N3 | J18: =J4*XAUconfig!J3 | K18: =K4*XAUconfig!K3 | L18: =L4*XAUconfig!L3 | M18: 0 | N18: =N4*XAUconfig!N3 | O18: 0 | P18: 0 | Q18: =Q4*XAUconfig!Q3 | R18: 0 | S18: 0 | T18: =T4*XAUconfig!T3 | U18: 0 | V18: 0 | W18: 0 | X18: =X4*XAUconfig!Y3 | Y18: =Y4*XAUconfig!Y3 | Z18: 0 | AA18: 0 | AB18: =AB4*XAUconfig!AB3 | AC18: 0 | AD18: 0 | AE18: 0 | AF18: 0 | AG18: =AG4*XAUconfig!AG3 | AH18: 0 | AI18: 0 | AJ18: =AJ4*XAUconfig!AJ3 | AK18: 0 | AL18: 0 | AM18: =AM4*XAUconfig!AM3 | AN18: 0 | AO18: 0 | AP18: =AP4*XAUconfig!AP3 | AQ18: 0 | AR18: 0 | AS18: 0 | AT18: 0 | AU18: =AU4*XAUconfig!AU3 | AV18: 0 | AW18: 0 | AX18: 0 | AY18: 0 | AZ18: 0 | BA18: 0 | BB18: 0 | BC18: 0 | BD18: 0 | BE18: 0 | BF18: 0 | BG18: 0 | BH18: 0 | BI18: 0
A19: Authorized Resources ($) | B19: 0 | C19: 0 | D19: 0 | E19: 0 | F19: 0 | G19: =G5*XAUconfig!G3 | H19: =H5*XAUconfig!H3 | I19: =I5*XAUconfig!N3 | J19: =J5*XAUconfig!J3 | K19: =K5*XAUconfig!K3 | L19: =L5*XAUconfig!L3 | M19: 0 | N19: =N5*XAUconfig!N3 | O19: 0 | P19: 0 | Q19: =Q5*XAUconfig!Q3 | R19: 0 | S19: 0 | T19: =T5*XAUconfig!T3 | U19: 0 | V19: 0 | W19: 0 | X19: =X5*XAUconfig!X3 | Y19: =Y5*XAUconfig!Y3 | Z19: =Z5*Inputs!B9 | AA19: 0 | AB19: =AB5*XAUconfig!AB3 | AC19: =AC5*Inputs!B9 | AD19: 0 | AE19: =AE5*Inputs!B9 | AF19: =AF5*Inputs!B9 | AG19: =AG5*XAUconfig!AG3 | AH19: =AH5*Inputs!B9 | AI19: =AI5*Inputs!B9 | AJ19: =AJ5*XAUconfig!AJ3 | AK19: =AK5*Inputs!B9 | AL19: =AL5*Inputs!B9 | AM19: =AM5*XAUconfig!AM3 | AN19: =AN5*Inputs!B9 | AO19: =AO5*Inputs!B9 | AP19: =AP5*XAUconfig!AP3 | AQ19: =AQ5*Inputs!B9 | AR19: =AR5*Inputs!B9 | AS19: =AS5*Inputs!B9 | AT19: =AT5*Inputs!B9 | AU19: =AU5*XAUconfig!AU3 | AV19: =AV5*Inputs!B9 | AW19: =AW5*Inputs!B9 | AX19: =AX5*Inputs!B9 | AY19: =AY5*Inputs!B9 | AZ19: =AZ5*Inputs!B9 | BA19: =BA5*Inputs!B9 | BB19: =BB5*Inputs!B9 | BC19: =BC5*Inputs!B9 | BD19: =BD5*Inputs!B9 | BE19: =BE5*Inputs!B9 | BF19: =BF5*Inputs!B9 | BG19: =BG5*Inputs!B9 | BH19: =BH5*Inputs!B9 | BI19: =BI5*Inputs!B9
A20: Releasable Resources ($) | B20: 0 | C20: 0 | D20: 0 | E20: 0 | F20: 0 | G20: =G6*XAUconfig!G3 | H20: =H6*XAUconfig!H3 | I20: =I6*Inputs!B9 | J20: =J6*XAUconfig!J3 | K20: =K6*Inputs!B9 | L20: =L6*XAUconfig!L3 | M20: =M6*Inputs!B9 | N20: =N6*XAUconfig!N3 | O20: =O6*Inputs!B9 | P20: =P6*Inputs!B9 | Q20: =Q6*XAUconfig!Q3 | R20: =R6*Inputs!B9 | S20: =S6*XAUconfig!S3 | T20: =T6*XAUconfig!T3 | U20: =U6*Inputs!B9 | V20: =V6*XAUconfig!V3 | W20: =W6*Inputs!B9 | X20: =X6*XAUconfig!X3 | Y20: =Y6*XAUconfig!Y3 | Z20: =Z6*Inputs!B9 | AA20: =AA6*Inputs!B9 | AB20: =AB6*XAUconfig!AB3 | AC20: =AC6*Inputs!B9 | AD20: =AD6*Inputs!B9 | AE20: =AE6*Inputs!B9 | AF20: 0 | AG20: =AG6*XAUconfig!AG3 | AH20: =AH6*Inputs!B9 | AI20: =AI6*Inputs!B9 | AJ20: =AJ6*XAUconfig!AJ3 | AK20: =AK6*Inputs!B9 | AL20: =AL6*Inputs!B9 | AM20: =AM6*XAUconfig!AM3 | AN20: =AN6*Inputs!B9 | AO20: =AO6*Inputs!B9 | AP20: =AP6*XAUconfig!AP3 | AQ20: =AQ6*Inputs!B9 | AR20: =AR6*Inputs!B9 | AS20: =AS6*Inputs!B9 | AT20: =AT6*Inputs!B9 | AU20: =AU6*XAUconfig!AU3 | AV20: =AV6*Inputs!B9 | AW20: =AW6*Inputs!B9 | AX20: =AX6*Inputs!B9 | AY20: =AY6*Inputs!B9 | AZ20: =AZ6*Inputs!B9 | BA20: =BA6*Inputs!B9 | BB20: =BB6*Inputs!B9 | BC20: =BC6*Inputs!B9 | BD20: =BD6*Inputs!B9 | BE20: =BE6*Inputs!B9 | BF20: =BF6*Inputs!B9 | BG20: =BG6*Inputs!B9 | BH20: =BH6*Inputs!B9 | BI20: =BI6*Inputs!B9
A21: Unlocked Resources ($) | B21: 0 | C21: 0 | D21: 0 | E21: 0 | F21: 0 | G21: =G7*XAUconfig!G3 | H21: =H7*XAUconfig!H3 | I21: =I7*XAUconfig!N3 | J21: =J7*XAUconfig!J3 | K21: =K7*XAUconfig!K3 | L21: =L7*XAUconfig!L3 | M21: 0 | N21: =N7*XAUconfig!N3 | O21: 0 | P21: 0 | Q21: =Q7*XAUconfig!Q3 | R21: 0 | S21: =S7*XAUconfig!S3 | T21: =T7*XAUconfig!T3 | U21: 0 | V21: =V7*XAUconfig!V3 | W21: =W7*XAUconfig!W3 | X21: =X7*XAUconfig!X3 | Y21: =Y7*XAUconfig!Y3 | Z21: =Z7*XAUconfig!Z3 | AA21: 0 | AB21: =AB7*XAUconfig!AB3 | AC21: =AC7*XAUconfig!AC3 | AD21: 0 | AE21: =AE7*XAUconfig!AE3 | AF21: =AF7*XAUconfig!AF3 | AG21: =AG7*XAUconfig!AG3 | AH21: =AH7*XAUconfig!AH3 | AI21: =AI7*Inputs!B9 | AJ21: =AJ7*XAUconfig!AJ3 | AK21: =AK7*XAUconfig!AK3 | AL21: =AL7*XAUconfig!AL3 | AM21: =AM7*XAUconfig!AM3 | AN21: =AN7*XAUconfig!AN3 | AO21: =AO7*XAUconfig!AO3 | AP21: =AP7*XAUconfig!AP3 | AQ21: =AQ7*XAUconfig!AQ3 | ... BI21: =BI7*XAUconfig!BI3
A22: Registration Fees ($) | B22: 0 | C22: 0 | D22: 0 | E22: 0 | F22: 0 | G22: =G8*XAUconfig!G3 | H22: =H8*XAUconfig!H3 | I22: =I8*XAUconfig!N3 | J22: =J8*XAUconfig!J3 | K22: =K8*XAUconfig!K3 | L22: =L8*XAUconfig!L3 | M22: 0 | N22: =N8*XAUconfig!N3 | O22: 0 | P22: 0 | Q22: =Q8*XAUconfig!Q3 | R22: 0 | S22: =S8*XAUconfig!S3 | T22: =T8*XAUconfig!T3 | U22: 0 | V22: =V8*XAUconfig!V3 | W22: 0 | X22: =X8*XAUconfig!X3 | Y22: =Y8*XAUconfig!Y3 | Z22: =Z8*XAUconfig!Z3 | AA22: 0 | AB22: =AB8*XAUconfig!AB3 | AC22: =AC8*XAUconfig!AC3 | AD22: 0 | AE22: =AE8*XAUconfig!AE3 | AF22: =AF8*XAUconfig!AF3 | AG22: =AG8*XAUconfig!AG3 | AH22: =AH8*XAUconfig!AH3 | AI22: =AI8*Inputs!B9 | AJ22: =AJ8*XAUconfig!AJ3 | AK22: =AK8*XAUconfig!AK3 | AL22: =AL8*XAUconfig!AL3 | AM22: =AM8*XAUconfig!AM3 | AN22: =AN8*XAUconfig!AN3 | AO22: =AO8*XAUconfig!AO3 | AP22: =AP8*XAUconfig!AP3 | AQ22: =AQ8*XAUconfig!AQ3 | ... BI22: =BI8*XAUconfig!BI3
A23: Unitization Fees ($) | B23: 0 | C23: 0 | D23: 0 | E23: 0 | F23: 0 | G23: =G10*XAUconfig!G3 | H23: =H10*XAUconfig!H3 | I23: =I10*XAUconfig!I3 | J23: =J10*XAUconfig!J3 | K23: =K10*XAUconfig!K3 | L23: =L10*XAUconfig!L3 | M23: 0 | N23: =N10*XAUconfig!N3 | O23: 0 | P23: 0 | Q23: =Q10*XAUconfig!Q3 | R23: 0 | S23: =S10*XAUconfig!S3 | T23: =T10*Inputs!B9 | U23: 0 | V23: =V10*XAUconfig!V3 | W23: 0 | X23: =X10*XAUconfig!X3 | Y23: =Y10*XAUconfig!Y3 | Z23: =Z10*XAUconfig!Z3 | AA23: 0 | AB23: =AB10*XAUconfig!AB3 | AC23: =AC10*XAUconfig!AC3 | AD23: 0 | AE23: =AE10*XAUconfig!AE3 | AF23: =AF10*XAUconfig!AF3 | AG23: =AG10*XAUconfig!AG3 | AH23: =AH10*XAUconfig!AH3 | AI23: =AI10*Inputs!B9 | AJ23: =AJ10*XAUconfig!AJ3 | AK23: =AK10*XAUconfig!AK3 | AL23: =AL10*XAUconfig!AL3 | AM23: =AM10*XAUconfig!AM3 | AN23: =AN10*XAUconfig!AN3 | AO23: =AO10*XAUconfig!AO3 | AP23: =AP10*XAUconfig!AP3 | AQ23: =AQ10*XAUconfig!AQ3 | ... BI23: =BI10*XAUconfig!BI3
A24: RealGold Token Minting Fees ($) | B24: 0 | C24: 0 | D24: 0 | E24: 0 | F24: 0 | G24: 0 | H24: 0 | I24: 0 | J24: =J13*XAUconfig!J3 | K24: =K13*XAUconfig!K3 | L24: =L13*XAUconfig!L3 | M24: =M13*XAUconfig!M3 | N24: =N13*XAUconfig!N3 | O24: =O13*XAUconfig!O3 | P24: =P13*XAUconfig!P3 | Q24: =Q13*XAUconfig!Q3 | ... BI24: =BI13*XAUconfig!BI3
A25: Total Reg & Unit Fee Rev ($) | B25: 0 | C25: 0 | D25: 0 | E25: 0 | F25: 0 | G25: =G22+G23 | H25: =H22+H23 | I25: =I22+I23 | J25: =J22+J23 | K25: =K22+K23 | L25: =L22+L23 | M25: 0 | N25: =N22+N23 | O25: 0 | P25: 0 | Q25: =Q22+Q23 | R25: 0 | S25: =S22+S23 | T25: =T22+T23 | U25: 0 | V25: =V22+V23 | W25: 0 | X25: =X22+X23 | Y25: =Y22+Y23 | Z25: =Z22+Z23 | AA25: 0 | AB25: =AB22+AB23 | AC25: =AC22+AC23 | AD25: =AD22+AD23 | AE25: =AE22+AE23 | AF25: =AF22+AF23 | AG25: =AG22+AG23 | AH25: =AH22+AH23 | AI25: =AI22+AI23 | ... BI25: =BI22+BI23
A26: Allocation to 1031 ($) | B26: 0 | C26: 0 | D26: 0 | E26: 0 | F26: 0 | G26: =G15*XAUconfig!G3 | H26: =H15*XAUconfig!H3 | I26: =I15*XAUconfig!I3 | J26: =J15*XAUconfig!J3 | K26: =K15*XAUconfig!K3 | L26: =L15*XAUconfig!L3 | M26: 0 | N26: =N15*XAUconfig!N3 | O26: 0 | P26: 0 | Q26: =Q15*XAUconfig!Q3 | R26: 0 | S26: =S15*XAUconfig!S3 | T26: =T15*XAUconfig!T3 | U26: 0 | V26: =V15*XAUconfig!V3 | W26: 0 | X26: =X15*XAUconfig!X3 | Y26: =Y15*XAUconfig!Y3 | Z26: =Z15*XAUconfig!Z3 | AA26: 0 | AB26: =AB15*XAUconfig!AB3 | AC26: =AC15*XAUconfig!AC3 | AD26: 0 | AE26: =AE15*XAUconfig!AE3 | AF26: =AF15*XAUconfig!AF3 | AG26: =AG15*XAUconfig!AG3 | AH26: =AH15*XAUconfig!AH3 | AI26: =AI15*Inputs!B9 | AJ26: =AJ15*XAUconfig!AJ3 | AK26: =AK15*XAUconfig!AK3 | AL26: =AL15*XAUconfig!AL3 | AM26: =AM15*XAUconfig!AM3 | AN26: =AN15*XAUconfig!AN3 | AO26: =AO15*XAUconfig!AO3 | AP26: =AP15*XAUconfig!AP3 | AQ26: =AQ15*XAUconfig!AQ3 | ... BI26: =BI15*XAUconfig!BI3
A27: Allocation to RealGold Treasury ($) | B27: 0 | C27: 0 | D27: 0 | E27: 0 | F27: 0 | G27: =G16*XAUconfig!G3 | H27: =H16*XAUconfig!H3 | I27: =I16*XAUconfig!I3 | J27: =J16*XAUconfig!J3 | K27: =K16*XAUconfig!K3 | L27: =L16*XAUconfig!L3 | M27: =M16*XAUconfig!M3 | N27: =N16*XAUconfig!N3 | O27: 0 | P27: 0 | Q27: =Q16*XAUconfig!Q3 | R27: 0 | S27: =S16*XAUconfig!S3 | T27: =T16*XAUconfig!T3 | U27: 0 | V27: =V16*XAUconfig!V3 | W27: 0 | X27: =X16*XAUconfig!X3 | Y27: =Y16*XAUconfig!Y3 | Z27: =Z16*XAUconfig!Z3 | AA27: 0 | AB27: =AB16*XAUconfig!AB3 | AC27: =AC16*XAUconfig!AC3 | AD27: 0 | AE27: =AE16*XAUconfig!AE3 | AF27: =AF16*XAUconfig!AF3 | AG27: =AG16*XAUconfig!AG3 | AH27: =AH16*XAUconfig!AH3 | AI27: =AI16*Inputs!B9 | AJ27: =AJ16*XAUconfig!AJ3 | AK27: =AK16*XAUconfig!AK3 | AL27: =AL16*XAUconfig!AL3 | AM27: =AM16*XAUconfig!AM3 | AN27: =AN16*XAUconfig!AN3 | AO27: =AO16*XAUconfig!AO3 | AP27: =AP16*XAUconfig!AP3 | AQ27: =AQ16*XAUconfig!AQ3 | ... BI27: =BI16*XAUconfig!BI3
A29: Resource Supply Cumulative Totals
A30: Cumulative Registered Resources (oz) | B30: 0 | C30: 0 | D30: 0 | E30: 0 | F30: 0 | G30: =sum(B4:G4) | H30: =sum(B4:H4) | I30: =sum(C4:I4) | J30: =sum(D4:J4) | K30: =sum(E4:K4) | L30: =sum(F4:L4) | M30: =sum(B4:M4) | N30: =sum(B4:N4) | O30: =sum(B4:O4) | P30: =sum(B4:P4) | Q30: =sum(B4:Q4) | R30: =sum(B4:R4) | S30: =sum(B4:S4) | T30: =sum(B4:T4) | U30: =sum(B4:U4) | V30: =sum(B4:V4) | W30: =sum(B4:W4) | X30: =sum(B4:X4) | Y30: =sum(B4:Y4) | Z30: =sum(B4:Z4) | AA30: =sum(B4:AA4) | AB30: =sum(B4:AB4) | AC30: =sum(B4:AC4) | AD30: =sum(B4:AD4) | AE30: =sum(B4:AE4) | AF30: =sum(B4:AF4) | AG30: =sum(B4:AG4) | AH30: =sum(B4:AH4) | AI30: =sum(B4:AI4) | AJ30: =sum(B4:AJ4) | AK30: =sum(B4:AK4) | AL30: =sum(B4:AL4) | AM30: =sum(B4:AM4) | AN30: =sum(B4:AN4) | AO30: =sum(B4:AO4) | AP30: =sum(B4:AP4) | AQ30: =sum(B4:AQ4) | AR30: =sum(B4:AR4) | AS30: =sum(B4:AS4) | AT30: =sum(B4:AT4) | AU30: =sum(B4:AU4) | AV30: =sum(B4:AV4) | AW30: =sum(B4:AW4) | AX30: =sum(B4:AX4) | AY30: =sum(B4:AY4) | AZ30: =sum(B4:AZ4) | BA30: =sum(B4:BA4) | BB30: =sum(B4:BB4) | BC30: =sum(B4:BC4) | BD30: =sum(B4:BD4) | BE30: =sum(B4:BE4) | BF30: =sum(B4:BF4) | BG30: =sum(B4:BG4) | BH30: =sum(B4:BH4) | BI30: =sum(B4:BI4)
A31: Cumulative Authorized Resources (oz) | B31: 0 | C31: 0 | D31: 0 | E31: 0 | F31: 0 | G31: =sum(B5:G5) | H31: =sum(B5:H5) | I31: =sum(B5:I5) | J31: =sum(B5:J5) | K31: =sum(B5:K5) | L31: =sum(B5:L5) | M31: =sum(B5:M5) | N31: =sum(M31,N5) | O31: =sum(N31,O5) | P31: =sum(O31,P5) | Q31: =sum(P31,Q5) | R31: =sum(Q31,R5) | S31: =sum(R31,S5) | T31: =sum(S31,T5) | U31: =sum(T31,U5) | ... BI31: =sum(BH31,BI5)
A32: Cumulative Releaseable Resources (oz) | B32: 0 | C32: 0 | D32: 0 | E32: 0 | F32: 0 | G32: =sum(B6:G6)/2 | H32: =sum(B6:H6)/2 | I32: =sum(B6:I6)/2 | J32: =sum(B6:J6) | K32: =sum(B6:K6) | L32: =sum(B6:L6) | M32: =sum(B6:M6) | N32: =sum(B6:N6) | O32: =sum(B6:O6) | P32: =sum(B6:P6) | Q32: =sum(B6:Q6) | R32: =sum(B6:R6) | S32: =sum(B6:S6) | T32: =sum(B6:T6) | U32: =sum(B6:U6) | V32: =sum(B6:V6) | W32: =sum(B6:W6) | X32: =sum(B6:X6) | Y32: =sum(B6:Y6) | Z32: =sum(B6:Z6) | AA32: =sum(B6:AA6) | AB32: =sum(B6:AB6) | AC32: =sum(B6:AC6) | AD32: =sum(B6:AD6) | AE32: =sum(B6:AE6) | AF32: =sum(B6:AF6) | AG32: =sum(B6:AG6) | AH32: =sum(B6:AH6) | AI32: =sum(B6:AI6) | AJ32: =sum(B6:AJ6) | AK32: =sum(B6:AK6) | AL32: =sum(B6:AL6) | AM32: =sum(B6:AM6) | AN32: =sum(B6:AN6) | AO32: =sum(B6:AO6) | AP32: =sum(B6:AP6) | AQ32: =sum(B6:AQ6) | AR32: =sum(B6:AR6) | AS32: =sum(B6:AS6) | AT32: =sum(B6:AT6) | AU32: =sum(B6:AU6) | AV32: =sum(B6:AV6) | AW32: =sum(B6:AW6) | AX32: =sum(B6:AX6) | AY32: =sum(B6:AY6) | AZ32: =sum(B6:AZ6) | BA32: =sum(B6:BA6) | BB32: =sum(B6:BB6) | BC32: =sum(B6:BC6) | BD32: =sum(B6:BD6) | BE32: =sum(B6:BE6) | BF32: =sum(B6:BF6) | BG32: =sum(B6:BG6) | BH32: =sum(B6:BH6) | BI32: =sum(B6:BI6)
A33: Cumulative Unlocked to Markets (oz) | B33: 0 | C33: 0 | D33: 0 | E33: 0 | F33: 0 | G33: =sum(G7:G8)/2 | H33: =sum(G7:H8)/2 | I33: =sum(G7:I8)/2 | J33: =sum(G7:J8)/2 | K33: =sum(G7:K8) | L33: =sum(G7:L8) | M33: =sum(G7:M8) | N33: =sum(G7:N8) | O33: =sum(G7:O8) | P33: =sum(G7:P8) | Q33: =sum(G7:Q8) | R33: =sum(G7:R8) | S33: =sum(G7:S8) | T33: =sum(B7:T8) | U33: =sum(G7:U8) | V33: =sum(G7:V8) | W33: =sum(G7:W8) | X33: =sum(G7:X8) | Y33: =sum(G7:Y8) | Z33: =sum(G7:Z8) | AA33: =sum(G7:AA8) | AB33: =sum(G7:AB8) | AC33: =sum(G7:AC8) | AD33: =sum(G7:AD8) | AE33: =sum(G7:AE8) | AF33: =sum(G7:AF8) | AG33: =sum(G7:AG8) | AH33: =sum(G7:AH8) | AI33: =sum(G7:AI8) | AJ33: =sum(G7:AJ8) | AK33: =sum(G7:AK8) | AL33: =sum(G7:AL8) | AM33: =sum(G7:AM8) | AN33: =sum(G7:AN8) | AO33: =sum(G7:AO8) | AP33: =sum(G7:AP8) | AQ33: =sum(G7:AQ8) | AR33: =sum(G7:AR8) | AS33: =sum(G7:AS8) | AT33: =sum(G7:AT8) | AU33: =sum(G7:AU8) | AV33: =sum(G7:AV8) | AW33: =sum(G7:AW8) | AX33: =sum(G7:AX8) | AY33: =sum(G7:AY8) | AZ33: =sum(G7:AZ8) | BA33: =sum(G7:BA8) | BB33: =sum(G7:BB8) | BC33: =sum(G7:BC8) | BD33: =sum(G7:BD8) | BE33: =sum(G7:BE8) | BF33: =sum(G7:BF8) | BG33: =sum(G7:BG8) | BH33: =sum(G7:BH8) | BI33: =sum(G7:BI8)
A34: Cumulative Allocation to RealGold Treasury (oz) | B34: 0 | C34: 0 | D34: 0 | E34: 0 | F34: 0 | G34: =sum(B16:G16) | H34: =sum(B16:H16) | I34: =sum(B16:I16) | J34: =sum(B16:J16) | K34: =sum(B16:K16) | L34: =sum(B16:L16) | M34: =sum(B16:M16) | N34: =sum(B16:N16) | O34: =sum(B16:O16) | P34: =sum(B16:P16) | Q34: =sum(B16:Q16) | R34: =sum(B16:R16) | S34: =sum(B16:S16) | T34: =sum(B16:T16) | U34: =sum(B16:U16) | V34: =sum(B16:V16) | W34: =sum(B16:W16) | X34: =sum(B16:X16) | Y34: =sum(B16:Y16) | Z34: =sum(B16:Z16) | AA34: =sum(B16:AA16) | AB34: =sum(B16:AB16) | AC34: =sum(B16:AC16) | AD34: =sum(B16:AD16) | AE34: =sum(B16:AE16) | AF34: =sum(B16:AF16) | AG34: =sum(B16:AG16) | AH34: =sum(B16:AH16) | AI34: =sum(B16:AI16) | AJ34: =sum(B16:AJ16) | AK34: =sum(B16:AK16) | AL34: =sum(B16:AL16) | AM34: =sum(B16:AM16) | AN34: =sum(B16:AN16) | AO34: =sum(B16:AO16) | AP34: =sum(B16:AP16) | AQ34: =sum(B16:AQ16) | AR34: =sum(B16:AR16) | AS34: =sum(B16:AS16) | AT34: =sum(B16:AT16) | AU34: =sum(B16:AU16) | AV34: =sum(B16:AV16) | AW34: =sum(B16:AW16) | AX34: =sum(B16:AX16) | AY34: =sum(B16:AY16) | AZ34: =sum(B16:AZ16) | BA34: =sum(B16:BA16) | BB34: =sum(B16:BB16) | BC34: =sum(B16:BC16) | BD34: =sum(B16:BD16) | BE34: =sum(B16:BE16) | BF34: =sum(B16:BF16) | BG34: =sum(B16:BG16) | BH34: =sum(B16:BH16) | BI34: =sum(B16:BI16)
A36: Cumulative Registered Resources ($) | B36: 0 | C36: 0 | D36: 0 | E36: 0 | F36: 0 | G36: =G18 | H36: =sum(B18:H18) | I36: =sum(B18:I18) | J36: =sum(B18:J18) | K36: =sum(B18:K18) | L36: =sum(B18:L18) | M36: =sum(B18:M18) | N36: =sum(B18:N18) | O36: =sum(B18:O18) | P36: =sum(B18:P18) | Q36: =sum(B18:Q18) | R36: =sum(B18:R18) | S36: =sum(B18:S18) | T36: =sum(B18:T18) | U36: =sum(B18:U18) | V36: =sum(B18:V18) | W36: =sum(B18:W18) | X36: =sum(B18:X18) | Y36: =sum(B18:Y18) | Z36: =sum(B18:Z18) | AA36: =sum(B18:AA18) | AB36: =sum(B18:AB18) | AC36: =sum(B18:AC18) | AD36: =sum(B18:AD18) | AE36: =sum(B18:AE18) | AF36: =sum(B18:AF18) | AG36: =sum(B18:AG18) | AH36: =sum(B18:AH18) | AI36: =sum(B18:AI18) | AJ36: =sum(B18:AJ18) | AK36: =sum(B18:AK18) | AL36: =sum(B18:AL18) | AM36: =sum(B18:AM18) | AN36: =sum(B18:AN18) | AO36: =sum(B18:AO18) | AP36: =sum(B18:AP18) | AQ36: =sum(B18:AQ18) | AR36: =sum(B18:AR18) | AS36: =sum(B18:AS18) | AT36: =sum(B18:AT18) | AU36: =sum(B18:AU18) | AV36: =sum(B18:AV18) | AW36: =sum(B18:AW18) | AX36: =sum(B18:AX18) | AY36: =sum(B18:AY18) | AZ36: =sum(B18:AZ18) | BA36: =sum(B18:BA18) | BB36: =sum(B18:BB18) | BC36: =sum(B18:BC18) | BD36: =sum(B18:BD18) | BE36: =sum(B18:BE18) | BF36: =sum(B18:BF18) | BG36: =sum(B18:BG18) | BH36: =sum(B18:BH18) | BI36: =sum(B18:BI18)
A37: Cumulative Authorized Resources ($) | B37: 0 | C37: 0 | D37: 0 | E37: 0 | F37: 0 | G37: =sum(B19:G19) | H37: =sum(C19:H19) | I37: =sum(D19:I19) | J37: =sum(E19:J19) | K37: =sum(B19:K19) | L37: =sum(B19:L19) | M37: =sum(B19:M19) | N37: =sum(B19:N19) | O37: =sum(B19:O19) | P37: =sum(B19:P19) | Q37: =sum(B19:Q19) | R37: =sum(B19:R19) | S37: =sum(B19:S19) | T37: =sum(B19:T19) | U37: =sum(B19:U19) | V37: =sum(B19:V19) | W37: =sum(B19:W19) | X37: =sum(B19:X19) | Y37: =sum(B19:Y19) | Z37: =sum(B19:Z19) | AA37: =sum(B19:AA19) | AB37: =sum(B19:AB19) | AC37: =sum(B19:AC19) | AD37: =sum(B19:AD19) | AE37: =sum(B19:AE19) | AF37: =sum(B19:AF19) | AG37: =sum(B19:AG19) | AH37: =sum(B19:AH19) | AI37: =sum(B19:AI19) | AJ37: =sum(B19:AJ19) | AK37: =sum(B19:AK19) | AL37: =sum(B19:AL19) | AM37: =sum(B19:AM19) | AN37: =sum(B19:AN19) | AO37: =sum(B19:AO19) | AP37: =sum(B19:AP19) | AQ37: =sum(B19:AQ19) | AR37: =sum(B19:AR19) | AS37: =sum(B19:AS19) | AT37: =sum(B19:AT19) | AU37: =sum(B19:AU19) | AV37: =sum(B19:AV19) | AW37: =sum(B19:AW19) | AX37: =sum(B19:AX19) | AY37: =sum(B19:AY19) | AZ37: =sum(B19:AZ19) | BA37: =sum(B19:BA19) | BB37: =sum(B19:BB19) | BC37: =sum(B19:BC19) | BD37: =sum(B19:BD19) | BE37: =sum(B19:BE19) | BF37: =sum(B19:BF19) | BG37: =sum(B19:BG19) | BH37: =sum(B19:BH19) | BI37: =sum(B19:BI19)
A38: Cumulative Releasable Resources ($) | B38: 0 | C38: 0 | D38: 0 | E38: 0 | F38: 0 | G38: =sum(B20:G20) | H38: =sum(C20:H20) | I38: =sum(D20:I20) | J38: =sum(E20:J20) | K38: =sum(B20:K20) | L38: =sum(B20:L20) | M38: =sum(B20:M20) | N38: =sum(B20:N20) | O38: =sum(B20:O20) | P38: =sum(B20:P20) | Q38: =sum(B20:Q20) | R38: =sum(B20:R20) | S38: =sum(B20:S20) | T38: =sum(B20:T20) | U38: =sum(B20:U20) | V38: =sum(B20:V20) | W38: =sum(B20:W20) | X38: =sum(B20:X20) | Y38: =sum(B20:Y20) | Z38: =sum(B20:Z20) | AA38: =sum(B20:AA20) | AB38: =sum(B20:AB20) | AC38: =sum(B20:AC20) | AD38: =sum(B20:AD20) | AE38: =sum(B20:AE20) | AF38: =sum(B20:AF20) | AG38: =sum(B20:AG20) | AH38: =sum(B20:AH20) | AI38: =sum(B20:AI20) | AJ38: =sum(B20:AJ20) | AK38: =sum(B20:AK20) | AL38: =sum(B20:AL20) | AM38: =sum(B20:AM20) | AN38: =sum(B20:AN20) | AO38: =sum(B20:AO20) | AP38: =sum(B20:AP20) | AQ38: =sum(B20:AQ20) | AR38: =sum(B20:AR20) | AS38: =sum(B20:AS20) | AT38: =sum(B20:AT20) | AU38: =sum(B20:AU20) | AV38: =sum(B20:AV20) | AW38: =sum(B20:AW20) | AX38: =sum(B20:AX20) | AY38: =sum(B20:AY20) | AZ38: =sum(B20:AZ20) | BA38: =sum(B20:BA20) | BB38: =sum(B20:BB20) | BC38: =sum(B20:BC20) | BD38: =sum(B20:BD20) | BE38: =sum(B20:BE20) | BF38: =sum(B20:BF20) | BG38: =sum(B20:BG20) | BH38: =sum(B20:BH20) | BI38: =sum(B20:BI20)
A39: Cumulative Unlocked Resources ($) | B39: 0 | C39: 0 | D39: 0 | E39: 0 | F39: 0 | G39: =G33*XAUconfig!G3 | H39: =H33*XAUconfig!H3 | I39: =I33*XAUconfig!I3 | J39: =J33*XAUconfig!J3 | K39: =K33*XAUconfig!K3 | L39: =L33*XAUconfig!L3 | M39: =M33*XAUconfig!M3 | N39: =N33*XAUconfig!N3 | ... AE39: =AE33*XAUconfig!AE3 | AF39: =AF33*Inputs!B9 | AG39: =AG33*XAUconfig!AG3 | AH39: =AH33*XAUconfig!AH3 | AI39: =AI33*XAUconfig!AI3 | AJ39: =AJ33*XAUconfig!AJ3 | AK39: =AK33*XAUconfig!AK3 | AL39: =AL33*XAUconfig!AL3 | AM39: =AM33*XAUconfig!AM3 | AN39: =AN33*XAUconfig!AN3 | ... BI39: =BI33*XAUconfig!BI3
A40: Cumulative Allocation to RealGold Treasury ($) | B40: 0 | C40: 0 | D40: 0 | E40: 0 | F40: 0 | G40: =G34*XAUconfig!G3 | H40: =H34*XAUconfig!H3 | I40: =I34*XAUconfig!I3 | J40: =J34*XAUconfig!J3 | K40: =K34*XAUconfig!K3 | L40: =L34*XAUconfig!L3 | M40: =M34*XAUconfig!M3 | N40: =N34*XAUconfig!N3 | ... BI40: =BI34*XAUconfig!BI3
A42: Annual Summaries | G42: 2025 | H42: 2026 | I42: 2027 | J42: 2028 | K42: 2029 | L42: Cumulative
A43: # of mines brought online | G43: =sum(B3:M3) | H43: =sum(N3:Y3) | I43: =sum(Z3:AK3) | J43: =sum(AL3:AW3) | K43: =sum(AV3:BI3) | L43: =SUM(G43:K43)
A44: Assayed Resources ($) | G44: =sum(B18:M18) | H44: =sum(N18:Y18) | I44: =sum(Z18:AK18) | J44: =sum(AL18:AW18) | K44: =sum(AV18:BI18) | L44: =SUM(G44:K44)
...

Sheet Token Supply (5yr)
A1: Token Supply (5yr) | B1: Jan '25 | C1: Feb '25 | D1: Mar '25 | E1: Apr '25 | F1: May '25 | G1: Jun '25 | H1: Jul '25 | I1: Aug '25 | J1: Sep '25 | K1: Oct '25 | L1: Nov '25 | M1: Dec '25 | N1: Jan '26 | O1: Feb '26 | P1: Mar '26 | Q1: Apr '26 | R1: May '26 | S1: Jun '26 | T1: Jul '26 | U1: Aug '26 | V1: Sep '26 | W1: Oct '26 | X1: Nov '26 | Y1: Dec '26 | Z1: Jan '27 | AA1: Feb '27 | AB1: Mar '27 | AC1: Apr '27 | AD1: May '27 | AE1: Jun '27 | AF1: Jul '27 | AG1: Aug '27 | AH1: Sep '27 | AI1: Oct '27 | AJ1: Nov '27 | AK1: Dec '27 | AL1: Jan '28 | AM1: Feb '28 | AN1: Mar '28 | AO1: Apr '28 | AP1: May '28 | AQ1: Jun '28 | AR1: Jul '28 | AS1: Aug '28 | AT1: Sep '28 | AU1: Oct '28 | AV1: Nov '28 | AW1: Dec '28 | AX1: Jan '29 | AY1: Feb '29 | AZ1: Mar '29 | BA1: Apr '29 | BB1: May '29 | BC1: Jun '29 | BD1: Jul '29 | BE1: Aug '29 | BF1: Sep '29 | BG1: Oct '29 | BH1: Nov '29 | BI1: Dec '29
A2: Unlocked Supply
A3: RealGold Treasury | B3: 0 | C3: 0 | D3: 0 | E3: 0 | F3: 0 | G3: ='Resource Supply (5yr)'!G14 | H3: ='Resource Supply (5yr)'!H14 | I3: 0 | J3: ='Resource Supply (5yr)'!J11 | K3: 0 | L3: ='Resource Supply (5yr)'!L11 | M3: ='Resource Supply (5yr)'!M14 | N3: ='Resource Supply (5yr)'!N14 | O3: ='Resource Supply (5yr)'!O14 | P3: ='Resource Supply (5yr)'!P14 | Q3: ='Resource Supply (5yr)'!Q14 | R3: ='Resource Supply (5yr)'!R14 | S3: ='Resource Supply (5yr)'!S14 | T3: ='Resource Supply (5yr)'!T14 | ... BI3: ='Resource Supply (5yr)'!BI14
A4: Courbet Mine | B4: 0 | C4: 0 | D4: 0 | E4: 0 | F4: 0 | G4: =('Resource Supply (5yr)'!G7-'Resource Supply (5yr)'!G10)*'Mine Inventory'!AF2 | H4: 0 | I4: 0 | J4: 0 | K4: 0 | L4: 0 | M4: 0 | N4: 0 | O4: 0 | P4: 0 | Q4: 0 | R4: 0 | S4: =('Resource Supply (5yr)'!S7-'Resource Supply (5yr)'!S10)*'Mine Inventory'!AF2 | T4: 0 | U4: 0 | V4: 0 | W4: 0 | X4: 0 | Y4: 0 | Z4: 0 | AA4: 0 | AB4: 0 | AC4: 0 | AD4: 0 | AE4: =('Resource Supply (5yr)'!S7-'Resource Supply (5yr)'!S10)*'Mine Inventory'!AF2 | AF4: 0 | AG4: 0 | AH4: 0 | AI4: 0 | AJ4: 0 | AK4: 0 | AL4: 0 | AM4: 0 | AN4: 0 | AO4: 0 | AP4: 0 | AQ4: =('Resource Supply (5yr)'!S7-'Resource Supply (5yr)'!S10)*'Mine Inventory'!AF2 | AR4: 0 | AS4: 0 | AT4: 0 | AU4: 0 | AV4: 0 | AW4: 0 | AX4: 0 | AY4: 0 | AZ4: 0 | BA4: 0 | BB4: 0 | BC4: =('Resource Supply (5yr)'!S7-'Resource Supply (5yr)'!S10)*'Mine Inventory'!AF2 | BD4: 0 | BE4: 0 | BF4: 0 | BG4: 0 | BH4: 0 | BI4: 0
A5: Mine 2 | B5: 0 | C5: 0 | D5: 0 | E5: 0 | F5: 0 | G5: 0 | H5: 0 | I5: 0 | J5: =('Resource Supply (5yr)'!J7-'Resource Supply (5yr)'!J10)*'Mine Inventory'!AF2 | K5: 0 | L5: 0 | M5: 0 | N5: 0 | O5: 0 | P5: 0 | Q5: 0 | R5: 0 | S5: 0 | T5: 0 | U5: 0 | V5: =('Mine Inventory'!W3-'Resource Supply (5yr)'!V10)*'Mine Inventory'!AF3 | W5: 0 | X5: 0 | Y5: 0 | Z5: 0 | AA5: 0 | AB5: 0 | AC5: 0 | AD5: 0 | AE5: 0 | AF5: 0 | AG5: 0 | AH5: =('Mine Inventory'!W3-'Resource Supply (5yr)'!V10)*'Mine Inventory'!AF3 | AI5: 0 | AJ5: 0 | AK5: 0 | AL5: 0 | AM5: 0 | AN5: 0 | AO5: 0 | AP5: 0 | AQ5: 0 | AR5: 0 | AS5: 0 | AT5: =('Mine Inventory'!W3-'Resource Supply (5yr)'!V10)*'Mine Inventory'!AF3 | AU5: 0 | AV5: 0 | AW5: 0 | AX5: 0 | AY5: 0 | AZ5: 0 | BA5: 0 | BB5: 0 | BC5: 0 | BD5: 0 | BE5: 0 | BF5: =('Mine Inventory'!W3-'Resource Supply (5yr)'!V10)*'Mine Inventory'!AF3 | BG5: 0 | BH5: 0 | BI5: 0
A6: Mine 3 | B6: 0 | C6: 0 | D6: 0 | E6: 0 | F6: 0 | G6: 0 | H6: 0 | I6: 0 | J6: 0 | K6: 0 | L6: 0 | M6: 0 | N6: ='Resource Supply (5yr)'!L16+('Resource Supply (5yr)'!N7-'Resource Supply (5yr)'!N10)*'Mine Inventory'!AF4 | O6: 0 | P6: 0 | Q6: 0 | R6: 0 | S6: 0 | T6: 0 | U6: 0 | V6: 0 | W6: 0 | X6: 0 | Y6: 0 | Z6: =('Resource Supply (5yr)'!Z7-'Resource Supply (5yr)'!Z10)*'Mine Inventory'!AF4 | AA6: 0 | AB6: 0 | AC6: 0 | AD6: 0 | AE6: 0 | AF6: 0 | AG6: 0 | AH6: 0 | AI6: 0 | AJ6: 0 | AK6: 0 | AL6: =('Resource Supply (5yr)'!AL7-'Resource Supply (5yr)'!AL10)*'Mine Inventory'!AF4 | AM6: 0 | AN6: 0 | AO6: 0 | AP6: 0 | AQ6: 0 | AR6: 0 | AS6: 0 | AT6: 0 | AU6: 0 | AV6: 0 | AW6: 0 | AX6: =('Resource Supply (5yr)'!AX7-'Resource Supply (5yr)'!AX10)*'Mine Inventory'!AF4 | AY6: 0 | AZ6: 0 | BA6: 0 | BB6: 0 | BC6: 0 | BD6: 0 | BE6: 0 | BF6: 0 | BG6: 0 | BH6: 0 | BI6: 0
A7: Mine 4 | B7: 0 | C7: 0 | D7: 0 | E7: 0 | F7: 0 | G7: 0 | H7: 0 | I7: 0 | J7: 0 | K7: 0 | L7: 0 | M7: 0 | N7: 0 | O7: 0 | P7: 0 | Q7: =('Resource Supply (5yr)'!Q7-'Resource Supply (5yr)'!Q10)*'Mine Inventory'!AF5 | R7: 0 | S7: 0 | T7: 0 | U7: 0 | V7: 0 | W7: 0 | X7: 0 | Y7: 0 | Z7: 0 | AA7: 0 | AB7: 0 | AC7: =('Resource Supply (5yr)'!AC7-'Resource Supply (5yr)'!AC10)*'Mine Inventory'!AF5 | AD7: 0 | AE7: 0 | AF7: 0 | AG7: 0 | AH7: 0 | AI7: 0 | AJ7: 0 | AK7: 0 | AL7: 0 | AM7: 0 | AN7: 0 | AO7: =('Resource Supply (5yr)'!AO7-'Resource Supply (5yr)'!AO10)*'Mine Inventory'!AF5 | AP7: 0 | AQ7: 0 | AR7: 0 | AS7: 0 | AT7: 0 | AU7: 0 | AV7: 0 | AW7: 0 | AX7: 0 | AY7: 0 | AZ7: 0 | BA7: =('Resource Supply (5yr)'!BA7-'Resource Supply (5yr)'!BA10)*'Mine Inventory'!AF5 | BB7: 0 | BC7: 0 | BD7: 0 | BE7: 0 | BF7: 0 | BG7: 0 | BH7: 0 | BI7: 0
A8: Mine 5 | B8: 0 | C8: 0 | D8: 0 | E8: 0 | F8: 0 | G8: 0 | H8: 0 | I8: 0 | J8: 0 | K8: 0 | L8: 0 | M8: 0 | N8: 0 | O8: 0 | P8: 0 | Q8: 0 | R8: 0 | S8: 0 | T8: =('Resource Supply (5yr)'!T7-'Resource Supply (5yr)'!T10)*'Mine Inventory'!AF6 | U8: 0 | V8: 0 | W8: 0 | X8: 0 | Y8: 0 | Z8: 0 | AA8: 0 | AB8: 0 | AC8: 0 | AD8: 0 | AE8: 0 | AF8: =('Resource Supply (5yr)'!AF7-'Resource Supply (5yr)'!AF10)*'Mine Inventory'!AF6 | AG8: 0 | AH8: 0 | AI8: 0 | AJ8: 0 | AK8: 0 | AL8: 0 | AM8: 0 | AN8: 0 | AO8: 0 | AP8: 0 | AQ8: 0 | AR8: =('Resource Supply (5yr)'!AR7-'Resource Supply (5yr)'!AR10)*'Mine Inventory'!AF6 | AS8: 0 | AT8: 0 | AU8: 0 | AV8: 0 | AW8: 0 | AX8: 0 | AY8: 0 | AZ8: 0 | BA8: 0 | BB8: 0 | BC8: 0 | BD8: =('Resource Supply (5yr)'!BD7-'Resource Supply (5yr)'!BD10)*'Mine Inventory'!AF6 | BE8: 0 | BF8: 0 | BG8: 0 | BH8: 0 | BI8: 0
A9: Mine 6 | B9: 0 | C9: 0 | D9: 0 | E9: 0 | F9: 0 | G9: 0 | H9: 0 | I9: 0 | J9: 0 | K9: 0 | L9: 0 | M9: 0 | N9: 0 | O9: 0 | P9: 0 | Q9: 0 | R9: 0 | S9: 0 | T9: 0 | U9: 0 | V9: 0 | W9: 0 | X9: 0 | Y9: =('Resource Supply (5yr)'!Y7-'Resource Supply (5yr)'!Y10)*'Mine Inventory'!AF7 | Z9: 0 | AA9: 0 | AB9: 0 | AC9: 0 | AD9: 0 | AE9: 0 | AF9: 0 | AG9: 0 | AH9: 0 | AI9: 0 | AJ9: 0 | AK9: =('Resource Supply (5yr)'!AK7-'Resource Supply (5yr)'!AK10)*'Mine Inventory'!AF7 | AL9: 0 | AM9: 0 | AN9: 0 | AO9: 0 | AP9: 0 | AQ9: 0 | AR9: 0 | AS9: 0 | AT9: 0 | AU9: 0 | AV9: 0 | AW9: =('Resource Supply (5yr)'!AW7-'Resource Supply (5yr)'!AW10)*'Mine Inventory'!AF7 | AX9: 0 | AY9: 0 | AZ9: 0 | BA9: 0 | BB9: 0 | BC9: 0 | BD9: 0 | BE9: 0 | BF9: 0 | BG9: 0 | BH9: 0 | BI9: =('Resource Supply (5yr)'!BI7-'Resource Supply (5yr)'!BI10)*'Mine Inventory'!AF7
A10: Mine 7 | B10: 0 | C10: 0 | D10: 0 | E10: 0 | F10: 0 | G10: 0 | H10: 0 | I10: 0 | J10: 0 | K10: 0 | L10: 0 | M10: 0 | N10: 0 | O10: 0 | P10: 0 | Q10: 0 | R10: 0 | S10: 0 | T10: 0 | U10: 0 | V10: 0 | W10: 0 | X10: 0 | Y10: 0 | Z10: 0 | AA10: 0 | AB10: =('Resource Supply (5yr)'!AB7-'Resource Supply (5yr)'!AB10)*'Mine Inventory'!AF8 | AC10: 0 | AD10: 0 | AE10: 0 | AF10: 0 | AG10: 0 | AH10: 0 | AI10: 0 | AJ10: 0 | AK10: 0 | AL10: 0 | AM10: 0 | AN10: =('Resource Supply (5yr)'!AN7-'Resource Supply (5yr)'!AN10)*'Mine Inventory'!AF8 | AO10: 0 | AP10: 0 | AQ10: 0 | AR10: 0 | AS10: 0 | AT10: 0 | AU10: 0 | AV10: 0 | AW10: 0 | AX10: 0 | AY10: 0 | AZ10: =('Resource Supply (5yr)'!AZ7-'Resource Supply (5yr)'!AZ10)*'Mine Inventory'!AF8 | BA10: 0 | BB10: 0 | BC10: 0 | BD10: 0 | BE10: 0 | BF10: 0 | BG10: 0 | BH10: 0 | BI10: 0
A11: Mine 8 | B11: 0 | C11: 0 | D11: 0 | E11: 0 | F11: 0 | G11: 0 | H11: 0 | I11: 0 | J11: 0 | K11: 0 | L11: 0 | M11: 0 | N11: 0 | O11: 0 | P11: 0 | Q11: 0 | R11: 0 | S11: 0 | T11: 0 | U11: 0 | V11: 0 | W11: 0 | X11: 0 | Y11: 0 | Z11: 0 | AA11: 0 | AB11: 0 | AC11: 0 | AD11: 0 | AE11: 0 | AF11: 0 | AG11: =('Resource Supply (5yr)'!AG7-'Resource Supply (5yr)'!AG10)*'Mine Inventory'!AF10 | AH11: 0 | AI11: 0 | AJ11: 0 | AK11: 0 | AL11: 0 | AM11: 0 | AN11: 0 | AO11: 0 | AP11: 0 | AQ11: 0 | AR11: 0 | AS11: =('Resource Supply (5yr)'!AS7-'Resource Supply (5yr)'!AS10)*'Mine Inventory'!AF10 | AT11: 0 | AU11: 0 | AV11: 0 | AW11: 0 | AX11: 0 | AY11: 0 | AZ11: 0 | BA11: 0 | BB11: 0 | BC11: 0 | BD11: 0 | BE11: =('Resource Supply (5yr)'!BE7-'Resource Supply (5yr)'!BE10)*'Mine Inventory'!AF10 | BF11: 0 | BG11: 0 | BH11: 0 | BI11: 0
